Workbook

Sheet Summary Tab
D1: E2 CHIEF Report Mapping to CDS
B2: Version | C2: Date | D2: Summary of Changes | E2: Signed Off By
B3: v0.1 | C3: 43515 | D3: Baselined and original mapping verified by data architecture.
B4: v0.2 | C4: 43517 | D4: Made changes from meeting 21/02.
B5: v0.3 | C5: 43523 | D5: Draft version including corrected DMS mappings (not yet ready for issue)
B6: v0.4 | C6: 43523 | D6: Ready for issue, pending inventory system mapping
B7: v0.5 | C7: 43523 | D7: Added detail on inventory system IDs, clarified outstanding question on Licence Value
B8: v0.6 | C8: 43537 | D8: Updated mapping of CHIEF Consignor from Seller to Exporter. Added mention of licence value unit.
B9: v1.0 | C9: 43566 | D9: Detailed Route Mapping provided in "ROE" tab following CSP feedback. Non-prescriptive layout provided. | E9: CC
B10: v1.1 | C10: 43810 | D10: Assumption section in "ROE" tab updated. Update in blue text | E10: CC
B11: v1.2 | C11: 43844 | D11: Trackings accepted and issued
B13: HOW TO USE THIS DOCUMENT - MUST READ BEFORE USING
B14: This mapping document shows how a CSP/Software Developer could recreate an equivalent CHIEF E2 Report using CDS data.
B15: HMRC will not provide a "CDS E2" - this document shows where CSPs & Software developers can find elements of the CHIEF E2 report in CDS declarations and DMS Notifications.
B16: This is a guidance document only and is not prescriptive. CSPs and Software Developers are free to compile reports in any way they wish.
B17: Many fields in the attached mapping are contained in other DES222 CHIEF reports; this mapping will provide a sound basis for mapping of other reports if required.
B18: A suggested layout of the E2 report is provided in the tab "Layout". Again, this is for guidance only and not prescriptive.
B20: The "E2 Data Mapping" tab explained:
B21: o Column C contains a reference (A-Z and 1-9) which shows where this data element should display in the report layout.
B22: o Column D shows each CHIEF EDIFACT in the CHIEF E2 report
B23: o Columns E and F show where the CDS equivalent of this CHIEF EDIFACT can be found in the CDS declaration
B24: o Where the CDS equivalent of the EDIFACT cannot be found in the declaration, Columns G and H show where it can be found in the DMS Notifications (e.g. DMSTAX)
B25: o Some CHIEF EDIFACTs have no direct CDS equivalents, and these are called out where appropriate
... B36: *note that the latest version of the TCM and DSSD can be found in the CDS Technical Documentation Folder in the HMRC Developer Hub. These documents are in the CDS 03 Customs Declaration Folder. Available at: https://developer.service.hmrc.gov.uk/guides/customs-declarations-end-to-end-service-guide/#end-to-end-user-journeys

Sheet E2 Data Mapping
C1: E2 CHIEF Report Mapping to CDS
B2: DES222 Report Number | C2: Description
B3: 7.3 | C3: Pre-lodgement/Entry Acceptance Advice (H2/E2, P2/X2)
B5: Field Name | C5: Readable Layout Reference | D5: CHIEF EDIFACT | E5: EUCDM D.E. | F5: WCO Label | G5: DMS Messages | H5: DMS Message Notification Element | I5: Notes
B6: Entry | C6: a | D6: ENT-REF | E6: - | F6: D014 | G6: DMSACC/ DMSRCV | H6: Response/Declaration/ID | I6: Closest equivalent we have in CDS is MRN - returned in the DMSACC/DMSRCV
B7: Entry | C7: b | D7: ENT-TYPE | E7: 1/1 & 1/2 See Notes | F7: D013 | I7: Closest equivalent we have in CDS is a combination of 1/1 & 1/2 - e.g. IMZ. This will inform the CHIEF equivalent: e.g. 0 = import frontier in CHIEF. Import frontier will become IMA/B/C.
B8: Version | C8: c | D8: ENT-VER-NO | E8: - | F8: 383 | G8: DMSACC/DMSRCV | H8: Declaration/VersionID | I8: This element will be sent in all trader notifications, and the value from the latest trader notification should be considered the most up-to-date. The version ID will remain constant until the declaration has been amended, and the incremented ID will be communicated in a DMSRCV or DMSACC trader notification.
B9: Route | C9: d | D9: ROE | E9: - | G9: See "ROE" tab for detailed logic on inferring the route based on DMS Notifications | H9: See "ROE" tab for detailed logic on inferring the route based on DMS Notifications | I9: ROE mapping: (Valid for both Imports and Exports) CDS Code Chief Code Route 1 1 Documentary Control 2 2 Physical / External Party Control 3 3 Non-Blocking Documentary Control 6 6 No Control required 0 N/A Risking not yet performed H H Pre-lodge pre-fix See "ROE" tab for detailed logic on inferring the route based on DMS Notifications
B10: at | C10: e | D10: GDS-EPU-NO | E10: - | I10: These EDIFACTs do not exist in CDS.
B11: at | C11: e | D11: + GDS-EPS-ID | E11: -
B12: status | C12: f | D12: ICS | E12: - | I12: For Imports: In response to an Arrival notification a CSP will receive an Inventory Linked Declaration Status Notification, which is a one-way status notification from CDS to CSPs, providing information on the declaration at specific points in the process. It is equivalent to a UKCIUM (as in CHIEF), but no response is required. This Status notification always includes the latest ICS code (customs status of the declaration) and ROE (route of examination) codes. ICS and ROE elements are in "Inventory Linked Declaration Notification – inventoryLinkingImportDeclarationStatusNotification" Refer to "SOE and ICS Codes" tab for valid ICS codes sent from DMS. 'Codes' in first code are valid for Imports. CSPs will in future be able submit an enquiry (using the Request Declaration Status API) to CDS to find out the latest status of an Imports declaration. This data will supplement the generation of various reports and queries used by CSP-linked Traders.
B13: Entry Accepted | C13: g | D13: ACPTNC-DTM | E13: - | F13: 023 | G13: DMSACC | H13: Response/Declaration/AcceptanceDateTime
B14: Office | C14: h | D14: ACPTNC-EPU-NO | E14: No CDS Equivalent | F14: - | I14: These EDIFACTs do not exist in CDS.
B15: Office | C15: h | D15: + ACPTNC-EPS-ID | E15: No CDS Equivalent | F15: -
B16: Present to Customs by | C16: i | D16: TDR-PRES-DTM | E16: No CDS Equivalent | F16: - | I16: This EDIFACT does not exist in CDS.
B17: Declarant Id | C17: j | D17: DECLT-TID | E17: 3/18 | F17: R123
B18: Submitting TURN | C18: k | D18: SUBMIT-TURN | E18: 3/18 or 3/20 See Notes | F18: R123/R004 | I18: If it is self submitted then DE 3/18 If direct or indirect representative then DE 3/20
B19: Declarant Reference | C19: l | D19: TDR-OWN-REF-ENT | E19: 2/5 | F19: D026
B20: Decln UCR | C20: m | D20: DECLN-UCR | E20: 2/1 | F20: D018
B21: part | C21: m | D21: + DECLN-PART-NO | E21: 2/1 | F21: D018
B22: MRN | C22: n | D22: MRN | E22: 2/1 (SEE NOTES) | F22: D018 | I22: In CHIEF, this would be the MRN of a previous document if the previous procedure was not in CHIEF. The MRN of the current declaration is mapped in this document to ENT-REF.
B23: Consignee | C23: o | D23: CNSGE-TID | E23: 3/16 | F23: R038
B24: Consignee | C24: o | D24: CNSGE-NAME | E24: 3/15 | F24: R037
B25: Consignor | C25: o | D25: CNSGR-TID | E25: 3/2 | F25: R051
B26: Consignor | C26: o | D26: CNSGR-NAME | E26: 3/1 | F26: R050
B27: Master UCR | C27: p | D27: MASTER-UCR | E27: 2/1 | F27: D018
B28: Inventory System | C28: q | D28: INVY-SYS-ID | E28: N/A | F28: - | I28: This identifies the inventory system to which the goods are being entered into. CCS-UK = CUK1 CNS = CNS1 Pentant = PNT1 MCP/Destin8 = FCP1 DHL = DHL1
B29: Location | C29: s | D29: GDS-LOCN-CODE | E29: 5/23 | F29: Concatenation of 242, L110, 410, L016, L017 | I29: This will only be applicable if the Goods Location identification qualifier (in WCO field 410) is declared with the value of 'U' to indicate a UNLOCODE.
B30: Status | C30: t | D30: SOE | E30: - | F30: - | H30: Refer to the 'Notes' for the 'ICS' CHIEF EDIFACT above for details on how this data element is communicated from CDS. | I30: SOE - Status of Entry CHIEF (from DES208): The ICS code for an Import entry summarises what has happened to the entry as well as identifying its current status. For Exports such a summary status needs to relate to an individual movement at a particular location. An Inventory system does not need to know how the movement reached its current state; only what that state now is. The SOE data item is introduced to provide simple status values as required for inventory control; the inventory interface includes the ICS as well, but in general this should be treated as additional information for display purposes only. CDS: Refer to 'Status (ICS)' for further details. Refer to "SOE and ICS Codes" tab for valid SOE codes sent from DMS.
B31: Total Packages | C31: u | D31: TOT-PKGS | E31: 6/18 | F31: 146
B32: Foreign Airport | C32: A | D32: FARP-CODE | E32: 5/21 | F32: L010 | I32: As defined in "Appendix 15B Airport codes" of the paper tariff
B33: Air Transport Costs | C33: B | D33: ATRPT-COST | E33: 4/9 | F33: 181 | I33: Amount in DE 4/9 with codes AR, AS, BR and BS when DE 5/21 is entered. i.e. as per the codes defined in the paper tariff "Appendix 10: D.E. 4/9 Additions and Deductions Codes" document. N.B. CSPs/SWDs may choose to split out some or all of the charges by 4/9 code - e.g. one line each for AR, AS, BR and BS. This is guidance only and should be tailored to suit trader needs.
B34: Freight Apportion ind | C34: C | D34: FRGT-APRT-CODE | E34: 4/9 See notes | F34: - | I34: Can be derived based on the first code entered in the 4/9 (see notes from Imports Declaration Submission Guide)
B35: Freight Charge | C35: D | D35: FRGT-CHGE | E35: 4/9 | F35: 181 | H35: May want to list 4/9 codes | I35: Amount in DE 4/9 with codes (AP, AR, BA, BR, AQ, AS, BS, BU) i.e. as per the codes defined in "Appendix 10: D.E. 4/9 Additions and Deductions Codes" of the Paper Tariff.
C36: D | D36: + FRGT-CHGE-CRRN | E36: - | F36: - | I36: Any currency code (e.g. GBP ) that is attached to DE 4/9
C37: D | D37: + FRGT-CHGE-EXCH | E37: 4/15 | F37: 118 | I37: Only declared when fixed rate of exchange agreed with HMRC. Otherwise exchange rate in CDS is used as a calculation parameter and won't be returned in a DMS Message.
B38: Discount | C38: E | D38: INV-DAMT | E38: 4/9 | F38: 181 | I38: Amount in DE 4/9 with code BH (i.e. codes as defined in the document "Appendix 10: D.E. 4/9 Additions and Deductions Codes" )
C39: E | D39: + INV-DAMT-CRRN | E39: - | F39: - | I39: Any currency code (e.g. GBP ) that is attached to DE 4/9
C40: E | D40: + INV-DAMT-EXCH | E40: 4/15 See notes | F40: 118 | I40: Only declared when fixed rate of exchange agreed with HMRC. Otherwise exchange rate in CDS is used as a calculation parameter and won't be returned in a DMS Message.
B41: Insurance | C41: F | D41: INS-AMT | E41: 4/9 | F41: 181 | I41: Amount in DE 4/9 with codes AK (i.e. codes as defined in the document "Appendix 10: D.E. 4/9 Additions and Deductions Codes" )
...

Sheet Layout
C1: E2 CHIEF Report Mapping to CDS
B3: Non-Prescriptive Report Layout

Sheet ROE
D1: E2 CHIEF Report Mapping to CDS
B3: Assumptions
B4: • Route is a CHIEF concept. It is not central to CDS processing, which is why an explicit routing code is not returned in the DMS response messages. It is only relevant when representing CDS information in a CHIEF-like format.
B5: • The CDS E2 report mapping will only be able to provide a route for the whole declaration – not for individual arrivals/re-arrivals (only applies to exports)
B6: • Once a declaration has gone down route 1, 2, or 3, it does not go to route 6 once controls have cleared – this mirrors CHIEF behaviour
B7: •A rejected declaration does not have a route assigned to it
B8: •A cancelled (invalidated) declaration will keep its existing pre-cancellation route
B9: •In order to distinguish between pre-lodged and arrived routes, trader notification data alone is not sufficient. The declaration type from the originally submitted declaration would need to be referred to, as well as if goods had arrived
B10: •The dwell timer is only relevant for routes 3 & 6 – the remedial actions needed under other routes can be executed immediately (no need to wait for the timer)
B11: • Once DMSROG has been received (Route 3) the goods can be collected, even when the tax calculation is not yet known (DMSTAX not yet received)
B12: •The current CDS implementation of the dwell timer means that by the time DMSCLE is received (an indicator for Route 6), the declaration is already cleared.
B14: Logic for Inferring Route
B15: •If a DMSCTL has been received for this declaration: route = 2
B16: •Else, if a DMSDOC has been received for this declaration:
C17: •If DMSTAX has not been received, but a DMSROG has been received for this declaration: route = 3 (i.e. declaration has not attracted customs debt, but declaration hasn’t yet cleared)
C18: •Else, if a DMSTAX has been received where //Response/status = ‘4’ (indicating final/non-provisional customs debt) followed by a DMSROG (note the sequence): route = 3 (i.e. declaration has attracted customs debt, which is not provisional, but the declaration hasn’t yet cleared)
C19: •Else, if a DMSRCV has been received for this declaration and declaration.type is one of (D,E,F,K), and goods have not arrived: route = H1
C20: •Else: route = 1
B21: •Else, if a DMSCPI, DMSTAX, DMSROG, or DMSCLE has been received for this declaration: route = 6
B22: •Else, if a DMSRCV has been received for this declaration, and declaration.type is one of (D,E,F,K), and goods have not arrived: route = H0
B23: •Else, if a DMSRCV or DMSACC has been received for this declaration: route = 0
B24: •Else, no route (e.g. if declaration is rejected)

Sheet ICS and SOE
C1: E2 CHIEF Report Mapping to CDS
B2: Status | C2: Code | D2: Description | E2: CHIEF Imports (ICS) Equivalent | F2: CHIEF Exports (SOE) Equivalent
B3: Declaration Validation | C3: 1 | D3: The declaration is currently within validation and is not yet accepted, registered or rejected. This code will be received for any initial linking of the declaration to the consignment on the inventory. | E3: 00 | F3: N/A
B4: Declaration Goods Release | C4: 2 | D4: This status will be received once the declaration has a positive customs position but either control or the debt is provisional. However, the goods can be released. This will be received as part of a Declaration Status Notification. | E4: 01 | F4: 7
B5: Declaration Clearance | C5: 3 | D5: This status will be received once the declaration has a positive customs position and the control/debt is finalised. The majority of declaration will move to this status and skip release. This will be received as part of a Declaration Status Notification. | E5: 01 | F5: 7
B6: Declaration Invalidated | C6: 4* | D6: This status will be received as part of a Declaration Status Notification once the decision has been taken to invalidate the declaration. At a later release, this value will be extended by use of additional status codes (see table below) in order to provide reasons for invalidation, to support current business processes. | E6: 92 / 07 / 09 / 05 | F6: 2 / 9
B7: Declaration Rejected | C7: 5 | D7: If the declaration is rejected, then a Declaration Status Notification will be received with this code. | E7: N/A | F7: N/A
B8: Declaration Handled Externally | C8: 6 | D8: This status will be received as part of a Declaration Status Notification once the decision has been taken to take the declaration off system. This will happen extremely rarely, e.g. a declaration with 999 items receives a partial quota allocation. | E8: N/A | F8: N/A
B9: Declaration Correction Validation | C9: 7 | D9: The amendment for the declaration is currently within validation and is not yet registered or rejected. This code will be received for any initial linking of the ‘stand-in’ declaration to the consignment on the inventory. | E9: 22 | F9: N/A
B10: Advance Declaration Registration | C10: 8 | D10: Will not be sent to CSPs | E10: N/A | F10: N/A
B11: Declaration Acceptance | C11: 9 | D11: Will not be sent to CSPs | E11: N/A | F11: N/A
B12: Declaration Acceptance at Goods Arrival | C12: 10 | D12: Will not be sent to CSPs | E12: N/A | F12: N/A
B13: Declaration Rejection at Goods Arrival | C13: 11 | D13: If the declaration fails re-validation at the point of arrival, then this notification will be sent to CSPs. (not relevant for import) | E13: - | F13: R
B14: Declaration Corrected | C14: 12 | D14: Will not be sent to CSPs | E14: N/A | F14: N/A
B15: Declaration Supplemented | C15: 13 | D15: Will not be sent to CSPs | E15: N/A | F15: N/A
B16: Declaration Risked | C16: 14 | D16: Notification that the declaration has now been risked and will contain a specific ROE code. | E16: N/A | F16: N/A
B17: Customs Position Determined | C17: 15 | D17: Will not be sent to CSPs | E17: N/A | F17: N/A
B18: Declaration Clearance after Goods Release | C18: 16 | D18: Will not be sent to CSPs | E18: N/A | F18: N/A
B19: Insufficient Guarantees | C19: 17 | D19: Will be sent as part of a Declaration Status Notification to inform of the need for the trader to take action on their deferment account. Suggests that there may be a delay to the declaration processing. (Not relevant for export) | E19: N/A | F19: -
B20: Departed | C20: D | D20: (Not relevant for import) | E20: - | F20: 8
B21: Frustrated | C21: F | D21: (Not relevant for import) | E21: - | F21: 8
B22: MUCR Values
B23: Consolidation is Open | C23: 0 | D23: The MUCR has been created and contains declaration, but is still open. (Not relevant for import) | E23: - | F23: 0
B24: Consolidation is closed but has no declarations | C24: 0 | D24: The MUCR has been created, and closed, but contains no declarations. (Not relevant for import) | E24: - | F24: N/A
B25: Consolidation is closed but does not have P2P | C25: C | D25: The consolidation is closed, but there are underlying declarations that do not have P2P. (Not relevant for import) | E25: - | F25: 1
B26: Consolidation has P2P | C26: 3 | D26: The consolidation is closed and all underlying declarations have P2P or have departed. (Not relevant for import) | E26: - | F26: 7
B29: * Status code 4 will be extended using below ICS codes for Exports only to show further reasons as to why the declaration was invalidated :
B30: Status | C30: ICS Code
B31: Invalidation at trader’s request | C31: 3
B32: Invalidation by customs due to major discrepancies | C32: 4
B33: No exit results received | C33: 5

Sheet 7.4
B2: Number | C2: Description | N2: CHIEF IMPORTS Report Name | O2: CDS Notif Equivalent
B3: 7.4 | C3: =VLOOKUP(B3,#REF!,2,FALSE) -> #REF! | N3: H7 | O3: =VLOOKUP(N3,#REF!,2,FALSE) -> #REF!
N4: E7 | O4: =VLOOKUP(N4,#REF!,2,FALSE) -> #REF!
B5: Field Name | C5: Field | D5: CHIEF EDIFACT | E5: Lookup from Data Arch | F5: CDS Decln. D.E. | G5: DMS Notification Element | H5: System Generated? | I5: Notes
B6: Entry | C6: a | D6: ENT-REF | E6: =INDEX('[1]Match Report'!$A$2:$BC$253,MATCH(LEFT(D6,LEN(D6)-1),'[1]Match Report'!$AL$2:$AL$253,0),7) -> #N/A | F6: =IFERROR(IF(VLOOKUP($D6,'E2 Data Mapping'!$D$5:$D$73,MATCH('7.4'!F$5,'E2 Data Mapping'!$D$5:$D$5,0),FALSE)=0,"",VLOOKUP($D6,'E2 Data Mapping'!$D$5:$D$73,MATCH('7.4'!F$5,'E2 Data Mapping'!$D$5:$D$5,0),FALSE)),"") | H6: =IFERROR(IF(VLOOKUP($D6,'E2 Data Mapping'!$D$5:$D$73,MATCH('7.4'!H$5,'E2 Data Mapping'!$D$5:$D$5,0),FALSE)=0,"",VLOOKUP($D6,'E2 Data Mapping'!$D$5:$D$73,MATCH('7.4'!H$5,'E2 Data Mapping'!$D$5:$D$5,0),FALSE)),"") | I6: =IFERROR(IF(VLOOKUP($D6,'E2 Data Mapping'!$D$5:$D$73,MATCH('7.4'!I$5,'E2 Data Mapping'!$D$5:$D$5,0),FALSE)=0,"",VLOOKUP($D6,'E2 Data Mapping'!$D$5:$D$73,MATCH('7.4'!I$5,'E2 Data Mapping'!$D$5:$D$5,0),FALSE)),"")
B7: Entry | C7: b | D7: ENT-TYPE | E7: =INDEX('[1]Match Report'!$A$2:$BC$253,MATCH(LEFT(D7,LEN(D7)-1),'[1]Match Report'!$AL$2:$AL$253,0),7) -> #N/A | F7: =IFERROR(IF(VLOOKUP($D7,'E2 Data Mapping'!$D$5:$D$73,MATCH('7.4'!F$5,'E2 Data Mapping'!$D$5:$D$5,0),FALSE)=0,"",VLOOKUP($D7,'E2 Data Mapping'!$D$5:$D$73,MATCH('7.4'!F$5,'E2 Data Mapping'!$D$5:$D$5,0),FALSE)),"") | H7: =IFERROR(IF(VLOOKUP($D7,'E2 Data Mapping'!$D$5:$D$73,MATCH('7.4'!H$5,'E2 Data Mapping'!$D$5:$D$5,0),FALSE)=0,"",VLOOKUP($D7,'E2 Data Mapping'!$D$5:$D$73,MATCH('7.4'!H$5,'E2 Data Mapping'!$D$5:$D$5,0),FALSE)),"") | I7: =IFERROR(IF(VLOOKUP($D7,'E2 Data Mapping'!$D$5:$D$73,MATCH('7.4'!I$5,'E2 Data Mapping'!$D$5:$D$5,0),FALSE)=0,"",VLOOKUP($D7,'E2 Data Mapping'!$D$5:$D$73,MATCH('7.4'!I$5,'E2 Data Mapping'!$D$5:$D$5,0),FALSE)),"")
B8: Version | C8: c | D8: ENT-VER-NO | E8: =INDEX('[1]Match Report'!$A$2:$BC$253,MATCH(LEFT(D8,LEN(D8)-1),'[1]Match Report'!$AL$2:$AL$253,0),7) -> #N/A | F8: =IFERROR(IF(VLOOKUP($D8,'E2 Data Mapping'!$D$5:$D$73,MATCH('7.4'!F$5,'E2 Data Mapping'!$D$5:$D$5,0),FALSE)=0,"",VLOOKUP($D8,'E2 Data Mapping'!$D$5:$D$73,MATCH('7.4'!F$5,'E2 Data Mapping'!$D$5:$D$5,0),FALSE)),"") | H8: =IFERROR(IF(VLOOKUP($D8,'E2 Data Mapping'!$D$5:$D$73,MATCH('7.4'!H$5,'E2 Data Mapping'!$D$5:$D$5,0),FALSE)=0,"",VLOOKUP($D8,'E2 Data Mapping'!$D$5:$D$73,MATCH('7.4'!H$5,'E2 Data Mapping'!$D$5:$D$5,0),FALSE)),"") | I8: =IFERROR(IF(VLOOKUP($D8,'E2 Data Mapping'!$D$5:$D$73,MATCH('7.4'!I$5,'E2 Data Mapping'!$D$5:$D$5,0),FALSE)=0,"",VLOOKUP($D8,'E2 Data Mapping'!$D$5:$D$73,MATCH('7.4'!I$5,'E2 Data Mapping'!$D$5:$D$5,0),FALSE)),"")
B9: Route | C9: d | D9: ROE | E9: =INDEX('[1]Match Report'!$A$2:$BC$253,MATCH(LEFT(D9,LEN(D9)-1),'[1]Match Report'!$AL$2:$AL$253,0),7) -> #N/A | F9: =IFERROR(IF(VLOOKUP($D9,'E2 Data Mapping'!$D$5:$D$73,MATCH('7.4'!F$5,'E2 Data Mapping'!$D$5:$D$5,0),FALSE)=0,"",VLOOKUP($D9,'E2 Data Mapping'!$D$5:$D$73,MATCH('7.4'!F$5,'E2 Data Mapping'!$D$5:$D$5,0),FALSE)),"") | H9: =IFERROR(IF(VLOOKUP($D9,'E2 Data Mapping'!$D$5:$D$73,MATCH('7.4'!H$5,'E2 Data Mapping'!$D$5:$D$5,0),FALSE)=0,"",VLOOKUP($D9,'E2 Data Mapping'!$D$5:$D$73,MATCH('7.4'!H$5,'E2 Data Mapping'!$D$5:$D$5,0),FALSE)),"") | I9: =IFERROR(IF(VLOOKUP($D9,'E2 Data Mapping'!$D$5:$D$73,MATCH('7.4'!I$5,'E2 Data Mapping'!$D$5:$D$5,0),FALSE)=0,"",VLOOKUP($D9,'E2 Data Mapping'!$D$5:$D$73,MATCH('7.4'!I$5,'E2 Data Mapping'!$D$5:$D$5,0),FALSE)),"")
B10: at | C10: e | D10: GDS-EPU-NO | E10: =INDEX('[1]Match Report'!$A$2:$BC$253,MATCH(LEFT(D10,LEN(D10)-1),'[1]Match Report'!$AL$2:$AL$253,0),7) -> #N/A | F10: =IFERROR(IF(VLOOKUP($D10,'E2 Data Mapping'!$D$5:$D$73,MATCH('7.4'!F$5,'E2 Data Mapping'!$D$5:$D$5,0),FALSE)=0,"",VLOOKUP($D10,'E2 Data Mapping'!$D$5:$D$73,MATCH('7.4'!F$5,'E2 Data Mapping'!$D$5:$D$5,0),FALSE)),"") | H10: =IFERROR(IF(VLOOKUP($D10,'E2 Data Mapping'!$D$5:$D$73,MATCH('7.4'!H$5,'E2 Data Mapping'!$D$5:$D$5,0),FALSE)=0,"",VLOOKUP($D10,'E2 Data Mapping'!$D$5:$D$73,MATCH('7.4'!H$5,'E2 Data Mapping'!$D$5:$D$5,0),FALSE)),"") | I10: =IFERROR(IF(VLOOKUP($D10,'E2 Data Mapping'!$D$5:$D$73,MATCH('7.4'!I$5,'E2 Data Mapping'!$D$5:$D$5,0),FALSE)=0,"",VLOOKUP($D10,'E2 Data Mapping'!$D$5:$D$73,MATCH('7.4'!I$5,'E2 Data Mapping'!$D$5:$D$5,0),FALSE)),"")
B11: at | C11: e | D11: + GDS-EPS-ID | E11: =INDEX('[1]Match Report'!$A$2:$BC$253,MATCH(LEFT(D11,LEN(D11)-1),'[1]Match Report'!$AL$2:$AL$253,0),7) -> #N/A | F11: =IFERROR(IF(VLOOKUP($D11,'E2 Data Mapping'!$D$5:$D$73,MATCH('7.4'!F$5,'E2 Data Mapping'!$D$5:$D$5,0),FALSE)=0,"",VLOOKUP($D11,'E2 Data Mapping'!$D$5:$D$73,MATCH('7.4'!F$5,'E2 Data Mapping'!$D$5:$D$5,0),FALSE)),"") | H11: =IFERROR(IF(VLOOKUP($D11,'E2 Data Mapping'!$D$5:$D$73,MATCH('7.4'!H$5,'E2 Data Mapping'!$D$5:$D$5,0),FALSE)=0,"",VLOOKUP($D11,'E2 Data Mapping'!$D$5:$D$73,MATCH('7.4'!H$5,'E2 Data Mapping'!$D$5:$D$5,0),FALSE)),"") | I11: =IFERROR(IF(VLOOKUP($D11,'E2 Data Mapping'!$D$5:$D$73,MATCH('7.4'!I$5,'E2 Data Mapping'!$D$5:$D$5,0),FALSE)=0,"",VLOOKUP($D11,'E2 Data Mapping'!$D$5:$D$73,MATCH('7.4'!I$5,'E2 Data Mapping'!$D$5:$D$5,0),FALSE)),"")
B12: status | C12: f | D12: ICS | E12: =INDEX('[1]Match Report'!$A$2:$BC$253,MATCH(LEFT(D12,LEN(D12)-1),'[1]Match Report'!$AL$2:$AL$253,0),7) -> #N/A | F12: =IFERROR(IF(VLOOKUP($D12,'E2 Data Mapping'!$D$5:$D$73,MATCH('7.4'!F$5,'E2 Data Mapping'!$D$5:$D$5,0),FALSE)=0,"",VLOOKUP($D12,'E2 Data Mapping'!$D$5:$D$73,MATCH('7.4'!F$5,'E2 Data Mapping'!$D$5:$D$5,0),FALSE)),"") | H12: =IFERROR(IF(VLOOKUP($D12,'E2 Data Mapping'!$D$5:$D$73,MATCH('7.4'!H$5,'E2 Data Mapping'!$D$5:$D$5,0),FALSE)=0,"",VLOOKUP($D12,'E2 Data Mapping'!$D$5:$D$73,MATCH('7.4'!H$5,'E2 Data Mapping'!$D$5:$D$5,0),FALSE)),"") | I12: =IFERROR(IF(VLOOKUP($D12,'E2 Data Mapping'!$D$5:$D$73,MATCH('7.4'!I$5,'E2 Data Mapping'!$D$5:$D$5,0),FALSE)=0,"",VLOOKUP($D12,'E2 Data Mapping'!$D$5:$D$73,MATCH('7.4'!I$5,'E2 Data Mapping'!$D$5:$D$5,0),FALSE)),"")
B13: Entry Accepted | C13: g | D13: ACPTNC-DTM | E13: =INDEX('[1]Match Report'!$A$2:$BC$253,MATCH(LEFT(D13,LEN(D13)-1),'[1]Match Report'!$AL$2:$AL$253,0),7) -> #N/A | F13: =IFERROR(IF(VLOOKUP($D13,'E2 Data Mapping'!$D$5:$D$73,MATCH('7.4'!F$5,'E2 Data Mapping'!$D$5:$D$5,0),FALSE)=0,"",VLOOKUP($D13,'E2 Data Mapping'!$D$5:$D$73,MATCH('7.4'!F$5,'E2 Data Mapping'!$D$5:$D$5,0),FALSE)),"") | H13: =IFERROR(IF(VLOOKUP($D13,'E2 Data Mapping'!$D$5:$D$73,MATCH('7.4'!H$5,'E2 Data Mapping'!$D$5:$D$5,0),FALSE)=0,"",VLOOKUP($D13,'E2 Data Mapping'!$D$5:$D$73,MATCH('7.4'!H$5,'E2 Data Mapping'!$D$5:$D$5,0),FALSE)),"") | I13: =IFERROR(IF(VLOOKUP($D13,'E2 Data Mapping'!$D$5:$D$73,MATCH('7.4'!I$5,'E2 Data Mapping'!$D$5:$D$5,0),FALSE)=0,"",VLOOKUP($D13,'E2 Data Mapping'!$D$5:$D$73,MATCH('7.4'!I$5,'E2 Data Mapping'!$D$5:$D$5,0),FALSE)),"")
B14: Office | C14: h | D14: ACPTNC-EPU-NO | E14: =INDEX('[1]Match Report'!$A$2:$BC$253,MATCH(LEFT(D14,LEN(D14)-1),'[1]Match Report'!$AL$2:$AL$253,0),7) -> #N/A | F14: =IFERROR(IF(VLOOKUP($D14,'E2 Data Mapping'!$D$5:$D$73,MATCH('7.4'!F$5,'E2 Data Mapping'!$D$5:$D$5,0),FALSE)=0,"",VLOOKUP($D14,'E2 Data Mapping'!$D$5:$D$73,MATCH('7.4'!F$5,'E2 Data Mapping'!$D$5:$D$5,0),FALSE)),"") | H14: =IFERROR(IF(VLOOKUP($D14,'E2 Data Mapping'!$D$5:$D$73,MATCH('7.4'!H$5,'E2 Data Mapping'!$D$5:$D$5,0),FALSE)=0,"",VLOOKUP($D14,'E2 Data Mapping'!$D$5:$D$73,MATCH('7.4'!H$5,'E2 Data Mapping'!$D$5:$D$5,0),FALSE)),"") | I14: =IFERROR(IF(VLOOKUP($D14,'E2 Data Mapping'!$D$5:$D$73,MATCH('7.4'!I$5,'E2 Data Mapping'!$D$5:$D$5,0),FALSE)=0,"",VLOOKUP($D14,'E2 Data Mapping'!$D$5:$D$73,MATCH('7.4'!I$5,'E2 Data Mapping'!$D$5:$D$5,0),FALSE)),"")
B15: Office | C15: h | D15: + ACPTNC-EPS-ID | E15: =INDEX('[1]Match Report'!$A$2:$BC$253,MATCH(LEFT(D15,LEN(D15)-1),'[1]Match Report'!$AL$2:$AL$253,0),7) -> #N/A | F15: =IFERROR(IF(VLOOKUP($D15,'E2 Data Mapping'!$D$5:$D$73,MATCH('7.4'!F$5,'E2 Data Mapping'!$D$5:$D$5,0),FALSE)=0,"",VLOOKUP($D15,'E2 Data Mapping'!$D$5:$D$73,MATCH('7.4'!F$5,'E2 Data Mapping'!$D$5:$D$5,0),FALSE)),"") | H15: =IFERROR(IF(VLOOKUP($D15,'E2 Data Mapping'!$D$5:$D$73,MATCH('7.4'!H$5,'E2 Data Mapping'!$D$5:$D$5,0),FALSE)=0,"",VLOOKUP($D15,'E2 Data Mapping'!$D$5:$D$73,MATCH('7.4'!H$5,'E2 Data Mapping'!$D$5:$D$5,0),FALSE)),"") | I15: =IFERROR(IF(VLOOKUP($D15,'E2 Data Mapping'!$D$5:$D$73,MATCH('7.4'!I$5,'E2 Data Mapping'!$D$5:$D$5,0),FALSE)=0,"",VLOOKUP($D15,'E2 Data Mapping'!$D$5:$D$73,MATCH('7.4'!I$5,'E2 Data Mapping'!$D$5:$D$5,0),FALSE)),"")
B16: Declarant Id | C16: j | D16: DECLT-TID | E16: =INDEX('[1]Match Report'!$A$2:$BC$253,MATCH(LEFT(D16,LEN(D16)-1),'[1]Match Report'!$AL$2:$AL$253,0),7) -> #N/A | F16: =IFERROR(IF(VLOOKUP($D16,'E2 Data Mapping'!$D$5:$D$73,MATCH('7.4'!F$5,'E2 Data Mapping'!$D$5:$D$5,0),FALSE)=0,"",VLOOKUP($D16,'E2 Data Mapping'!$D$5:$D$73,MATCH('7.4'!F$5,'E2 Data Mapping'!$D$5:$D$5,0),FALSE)),"") | H16: =IFERROR(IF(VLOOKUP($D16,'E2 Data Mapping'!$D$5:$D$73,MATCH('7.4'!H$5,'E2 Data Mapping'!$D$5:$D$5,0),FALSE)=0,"",VLOOKUP($D16,'E2 Data Mapping'!$D$5:$D$73,MATCH('7.4'!H$5,'E2 Data Mapping'!$D$5:$D$5,0),FALSE)),"") | I16: =IFERROR(IF(VLOOKUP($D16,'E2 Data Mapping'!$D$5:$D$73,MATCH('7.4'!I$5,'E2 Data Mapping'!$D$5:$D$5,0),FALSE)=0,"",VLOOKUP($D16,'E2 Data Mapping'!$D$5:$D$73,MATCH('7.4'!I$5,'E2 Data Mapping'!$D$5:$D$5,0),FALSE)),"")
B17: Submitting TURN | C17: k | D17: SUBMIT-TURN | E17: =INDEX('[1]Match Report'!$A$2:$BC$253,MATCH(LEFT(D17,LEN(D17)-1),'[1]Match Report'!$AL$2:$AL$253,0),7) -> #N/A | F17: =IFERROR(IF(VLOOKUP($D17,'E2 Data Mapping'!$D$5:$D$73,MATCH('7.4'!F$5,'E2 Data Mapping'!$D$5:$D$5,0),FALSE)=0,"",VLOOKUP($D17,'E2 Data Mapping'!$D$5:$D$73,MATCH('7.4'!F$5,'E2 Data Mapping'!$D$5:$D$5,0),FALSE)),"") | H17: =IFERROR(IF(VLOOKUP($D17,'E2 Data Mapping'!$D$5:$D$73,MATCH('7.4'!H$5,'E2 Data Mapping'!$D$5:$D$5,0),FALSE)=0,"",VLOOKUP($D17,'E2 Data Mapping'!$D$5:$D$73,MATCH('7.4'!H$5,'E2 Data Mapping'!$D$5:$D$5,0),FALSE)),"") | I17: =IFERROR(IF(VLOOKUP($D17,'E2 Data Mapping'!$D$5:$D$73,MATCH('7.4'!I$5,'E2 Data Mapping'!$D$5:$D$5,0),FALSE)=0,"",VLOOKUP($D17,'E2 Data Mapping'!$D$5:$D$73,MATCH('7.4'!I$5,'E2 Data Mapping'!$D$5:$D$5,0),FALSE)),"")
... B20: part | C20: m | D20: + DECLN-PART-NO | E20: =INDEX('[1]Match Report'!$A$2:$BC$253,MATCH(LEFT(D20,LEN(D20)-1),'[1]Match Report'!$AL$2:$AL$253,0),7) -> #N/A | F20: =IFERROR(IF(VLOOKUP($D20,'E2 Data Mapping'!$D$5:$D$73,MATCH('7.4'!F$5,'E2 Data Mapping'!$D$5:$D$5,0),FALSE)=0,"",VLOOKUP($D20,'E2 Data Mapping'!$D$5:$D$73,MATCH('7.4'!F$5,'E2 Data Mapping'!$D$5:$D$5,0),FALSE)),"") | H20: =IFERROR(IF(VLOOKUP($D20,'E2 Data Mapping'!$D$5:$D$73,MATCH('7.4'!H$5,'E2 Data Mapping'!$D$5:$D$5,0),FALSE)=0,"",VLOOKUP($D20,'E2 Data Mapping'!$D$5:$D$73,MATCH('7.4'!H$5,'E2 Data Mapping'!$D$5:$D$5,0),FALSE)),"") | I20: =IFERROR(IF(VLOOKUP($D20,'E2 Data Mapping'!$D$5:$D$73,MATCH('7.4'!I$5,'E2 Data Mapping'!$D$5:$D$5,0),FALSE)=0,"",VLOOKUP($D20,'E2 Data Mapping'!$D$5:$D$73,MATCH('7.4'!I$5,'E2 Data Mapping'!$D$5:$D$5,0),FALSE)),"")
B21: MRN | C21: n | D21: MRN | E21: =INDEX('[1]Match Report'!$A$2:$BC$253,MATCH(LEFT(D21,LEN(D21)-1),'[1]Match Report'!$AL$2:$AL$253,0),7) -> #N/A | F21: =IFERROR(IF(VLOOKUP($D21,'E2 Data Mapping'!$D$5:$D$73,MATCH('7.4'!F$5,'E2 Data Mapping'!$D$5:$D$5,0),FALSE)=0,"",VLOOKUP($D21,'E2 Data Mapping'!$D$5:$D$73,MATCH('7.4'!F$5,'E2 Data Mapping'!$D$5:$D$5,0),FALSE)),"") | H21: Y | I21: No equivalent found in Technical Completion Matrix
B22: Consignee | C22: o | D22: CNSGE-TID | E22: =INDEX('[1]Match Report'!$A$2:$BC$253,MATCH(LEFT(D22,LEN(D22)-1),'[1]Match Report'!$AL$2:$AL$253,0),7) -> 3/16 | F22: =IFERROR(IF(VLOOKUP($D22,'E2 Data Mapping'!$D$5:$D$73,MATCH('7.4'!F$5,'E2 Data Mapping'!$D$5:$D$5,0),FALSE)=0,"",VLOOKUP($D22,'E2 Data Mapping'!$D$5:$D$73,MATCH('7.4'!F$5,'E2 Data Mapping'!$D$5:$D$5,0),FALSE)),"") | H22: =IFERROR(IF(VLOOKUP($D22,'E2 Data Mapping'!$D$5:$D$73,MATCH('7.4'!H$5,'E2 Data Mapping'!$D$5:$D$5,0),FALSE)=0,"",VLOOKUP($D22,'E2 Data Mapping'!$D$5:$D$73,MATCH('7.4'!H$5,'E2 Data Mapping'!$D$5:$D$5,0),FALSE)),"") | I22: =IFERROR(IF(VLOOKUP($D22,'E2 Data Mapping'!$D$5:$D$73,MATCH('7.4'!I$5,'E2 Data Mapping'!$D$5:$D$5,0),FALSE)=0,"",VLOOKUP($D22,'E2 Data Mapping'!$D$5:$D$73,MATCH('7.4'!I$5,'E2 Data Mapping'!$D$5:$D$5,0),FALSE)),"")
B23: Consignor | C23: o | D23: CNSGE-NAME | E23: =INDEX('[1]Match Report'!$A$2:$BC$253,MATCH(LEFT(D23,LEN(D23)-1),'[1]Match Report'!$AL$2:$AL$253,0),7) -> #N/A | F23: =IFERROR(IF(VLOOKUP($D23,'E2 Data Mapping'!$D$5:$D$73,MATCH('7.4'!F$5,'E2 Data Mapping'!$D$5:$D$5,0),FALSE)=0,"",VLOOKUP($D23,'E2 Data Mapping'!$D$5:$D$73,MATCH('7.4'!F$5,'E2 Data Mapping'!$D$5:$D$5,0),FALSE)),"") | H23: =IFERROR(IF(VLOOKUP($D23,'E2 Data Mapping'!$D$5:$D$73,MATCH('7.4'!H$5,'E2 Data Mapping'!$D$5:$D$5,0),FALSE)=0,"",VLOOKUP($D23,'E2 Data Mapping'!$D$5:$D$73,MATCH('7.4'!H$5,'E2 Data Mapping'!$D$5:$D$5,0),FALSE)),"") | I23: =IFERROR(IF(VLOOKUP($D23,'E2 Data Mapping'!$D$5:$D$73,MATCH('7.4'!I$5,'E2 Data Mapping'!$D$5:$D$5,0),FALSE)=0,"",VLOOKUP($D23,'E2 Data Mapping'!$D$5:$D$73,MATCH('7.4'!I$5,'E2 Data Mapping'!$D$5:$D$5,0),FALSE)),"")
B24: Consignor | C24: o | D24: CNSGR-TID | E24: =INDEX('[1]Match Report'!$A$2:$BC$253,MATCH(LEFT(D24,LEN(D24)-1),'[1]Match Report'!$AL$2:$AL$253,0),7) -> #N/A | F24: =IFERROR(IF(VLOOKUP($D24,'E2 Data Mapping'!$D$5:$D$73,MATCH('7.4'!F$5,'E2 Data Mapping'!$D$5:$D$5,0),FALSE)=0,"",VLOOKUP($D24,'E2 Data Mapping'!$D$5:$D$73,MATCH('7.4'!F$5,'E2 Data Mapping'!$D$5:$D$5,0),FALSE)),"") | H24: =IFERROR(IF(VLOOKUP($D24,'E2 Data Mapping'!$D$5:$D$73,MATCH('7.4'!H$5,'E2 Data Mapping'!$D$5:$D$5,0),FALSE)=0,"",VLOOKUP($D24,'E2 Data Mapping'!$D$5:$D$73,MATCH('7.4'!H$5,'E2 Data Mapping'!$D$5:$D$5,0),FALSE)),"") | I24: =IFERROR(IF(VLOOKUP($D24,'E2 Data Mapping'!$D$5:$D$73,MATCH('7.4'!I$5,'E2 Data Mapping'!$D$5:$D$5,0),FALSE)=0,"",VLOOKUP($D24,'E2 Data Mapping'!$D$5:$D$73,MATCH('7.4'!I$5,'E2 Data Mapping'!$D$5:$D$5,0),FALSE)),"")
B25: Consignor | C25: o | D25: CNSGR-NAME | E25: =INDEX('[1]Match Report'!$A$2:$BC$253,MATCH(LEFT(D25,LEN(D25)-1),'[1]Match Report'!$AL$2:$AL$253,0),7) -> #N/A | F25: =IFERROR(IF(VLOOKUP($D25,'E2 Data Mapping'!$D$5:$D$73,MATCH('7.4'!F$5,'E2 Data Mapping'!$D$5:$D$5,0),FALSE)=0,"",VLOOKUP($D25,'E2 Data Mapping'!$D$5:$D$73,MATCH('7.4'!F$5,'E2 Data Mapping'!$D$5:$D$5,0),FALSE)),"") | H25: =IFERROR(IF(VLOOKUP($D25,'E2 Data Mapping'!$D$5:$D$73,MATCH('7.4'!H$5,'E2 Data Mapping'!$D$5:$D$5,0),FALSE)=0,"",VLOOKUP($D25,'E2 Data Mapping'!$D$5:$D$73,MATCH('7.4'!H$5,'E2 Data Mapping'!$D$5:$D$5,0),FALSE)),"") | I25: =IFERROR(IF(VLOOKUP($D25,'E2 Data Mapping'!$D$5:$D$73,MATCH('7.4'!I$5,'E2 Data Mapping'!$D$5:$D$5,0),FALSE)=0,"",VLOOKUP($D25,'E2 Data Mapping'!$D$5:$D$73,MATCH('7.4'!I$5,'E2 Data Mapping'!$D$5:$D$5,0),FALSE)),"")
B26: Master UCR | C26: p | D26: MASTER-UCR | E26: =INDEX('[1]Match Report'!$A$2:$BC$253,MATCH(LEFT(D26,LEN(D26)-1),'[1]Match Report'!$AL$2:$AL$253,0),7) -> #N/A | F26: =IFERROR(IF(VLOOKUP($D26,'E2 Data Mapping'!$D$5:$D$73,MATCH('7.4'!F$5,'E2 Data Mapping'!$D$5:$D$5,0),FALSE)=0,"",VLOOKUP($D26,'E2 Data Mapping'!$D$5:$D$73,MATCH('7.4'!F$5,'E2 Data Mapping'!$D$5:$D$5,0),FALSE)),"") | H26: =IFERROR(IF(VLOOKUP($D26,'E2 Data Mapping'!$D$5:$D$73,MATCH('7.4'!H$5,'E2 Data Mapping'!$D$5:$D$5,0),FALSE)=0,"",VLOOKUP($D26,'E2 Data Mapping'!$D$5:$D$73,MATCH('7.4'!H$5,'E2 Data Mapping'!$D$5:$D$5,0),FALSE)),"") | I26: =IFERROR(IF(VLOOKUP($D26,'E2 Data Mapping'!$D$5:$D$73,MATCH('7.4'!I$5,'E2 Data Mapping'!$D$5:$D$5,0),FALSE)=0,"",VLOOKUP($D26,'E2 Data Mapping'!$D$5:$D$73,MATCH('7.4'!I$5,'E2 Data Mapping'!$D$5:$D$5,0),FALSE)),"")
B27: Inventory System | C27: q | D27: INVY-SYS-ID | E27: =INDEX('[1]Match Report'!$A$2:$BC$253,MATCH(LEFT(D27,LEN(D27)-1),'[1]Match Report'!$AL$2:$AL$253,0),7) -> #N/A | F27: =IFERROR(IF(VLOOKUP($D27,'E2 Data Mapping'!$D$5:$D$73,MATCH('7.4'!F$5,'E2 Data Mapping'!$D$5:$D$5,0),FALSE)=0,"",VLOOKUP($D27,'E2 Data Mapping'!$D$5:$D$73,MATCH('7.4'!F$5,'E2 Data Mapping'!$D$5:$D$5,0),FALSE)),"") | H27: =IFERROR(IF(VLOOKUP($D27,'E2 Data Mapping'!$D$5:$D$73,MATCH('7.4'!H$5,'E2 Data Mapping'!$D$5:$D$5,0),FALSE)=0,"",VLOOKUP($D27,'E2 Data Mapping'!$D$5:$D$73,MATCH('7.4'!H$5,'E2 Data Mapping'!$D$5:$D$5,0),FALSE)),"") | I27: =IFERROR(IF(VLOOKUP($D27,'E2 Data Mapping'!$D$5:$D$73,MATCH('7.4'!I$5,'E2 Data Mapping'!$D$5:$D$5,0),FALSE)=0,"",VLOOKUP($D27,'E2 Data Mapping'!$D$5:$D$73,MATCH('7.4'!I$5,'E2 Data Mapping'!$D$5:$D$5,0),FALSE)),"")
B28: Location | C28: s | D28: GDS-LOCN-CODE | E28: =INDEX('[1]Match Report'!$A$2:$BC$253,MATCH(LEFT(D28,LEN(D28)-1),'[1]Match Report'!$AL$2:$AL$253,0),7) -> 5/23 | F28: =IFERROR(IF(VLOOKUP($D28,'E2 Data Mapping'!$D$5:$D$73,MATCH('7.4'!F$5,'E2 Data Mapping'!$D$5:$D$5,0),FALSE)=0,"",VLOOKUP($D28,'E2 Data Mapping'!$D$5:$D$73,MATCH('7.4'!F$5,'E2 Data Mapping'!$D$5:$D$5,0),FALSE)),"") | H28: =IFERROR(IF(VLOOKUP($D28,'E2 Data Mapping'!$D$5:$D$73,MATCH('7.4'!H$5,'E2 Data Mapping'!$D$5:$D$5,0),FALSE)=0,"",VLOOKUP($D28,'E2 Data Mapping'!$D$5:$D$73,MATCH('7.4'!H$5,'E2 Data Mapping'!$D$5:$D$5,0),FALSE)),"") | I28: =IFERROR(IF(VLOOKUP($D28,'E2 Data Mapping'!$D$5:$D$73,MATCH('7.4'!I$5,'E2 Data Mapping'!$D$5:$D$5,0),FALSE)=0,"",VLOOKUP($D28,'E2 Data Mapping'!$D$5:$D$73,MATCH('7.4'!I$5,'E2 Data Mapping'!$D$5:$D$5,0),FALSE)),"")
B29: Total Packages | C29: u | D29: TOT-PKGS | E29: =INDEX('[1]Match Report'!$A$2:$BC$253,MATCH(LEFT(D29,LEN(D29)-1),'[1]Match Report'!$AL$2:$AL$253,0),7) -> 6/18 | F29: =IFERROR(IF(VLOOKUP($D29,'E2 Data Mapping'!$D$5:$D$73,MATCH('7.4'!F$5,'E2 Data Mapping'!$D$5:$D$5,0),FALSE)=0,"",VLOOKUP($D29,'E2 Data Mapping'!$D$5:$D$73,MATCH('7.4'!F$5,'E2 Data Mapping'!$D$5:$D$5,0),FALSE)),"") | H29: =IFERROR(IF(VLOOKUP($D29,'E2 Data Mapping'!$D$5:$D$73,MATCH('7.4'!H$5,'E2 Data Mapping'!$D$5:$D$5,0),FALSE)=0,"",VLOOKUP($D29,'E2 Data Mapping'!$D$5:$D$73,MATCH('7.4'!H$5,'E2 Data Mapping'!$D$5:$D$5,0),FALSE)),"") | I29: =IFERROR(IF(VLOOKUP($D29,'E2 Data Mapping'!$D$5:$D$73,MATCH('7.4'!I$5,'E2 Data Mapping'!$D$5:$D$5,0),FALSE)=0,"",VLOOKUP($D29,'E2 Data Mapping'!$D$5:$D$73,MATCH('7.4'!I$5,'E2 Data Mapping'!$D$5:$D$5,0),FALSE)),"")
B30: Items Added | C30: A | D30: ADD-ITEM-NO | E30: =INDEX('[1]Match Report'!$A$2:$BC$253,MATCH(LEFT(D30,LEN(D30)-1),'[1]Match Report'!$AL$2:$AL$253,0),7) -> #N/A | F30: =IFERROR(IF(VLOOKUP($D30,'E2 Data Mapping'!$D$5:$D$73,MATCH('7.4'!F$5,'E2 Data Mapping'!$D$5:$D$5,0),FALSE)=0,"",VLOOKUP($D30,'E2 Data Mapping'!$D$5:$D$73,MATCH('7.4'!F$5,'E2 Data Mapping'!$D$5:$D$5,0),FALSE)),"") | H30: TBC | I30: =IFERROR(IF(VLOOKUP($D30,'E2 Data Mapping'!$D$5:$D$73,MATCH('7.4'!I$5,'E2 Data Mapping'!$D$5:$D$5,0),FALSE)=0,"",VLOOKUP($D30,'E2 Data Mapping'!$D$5:$D$73,MATCH('7.4'!I$5,'E2 Data Mapping'!$D$5:$D$5,0),FALSE)),"")
B31: Items Deleted | C31: B | D31: DEL-ITEM-NO | E31: =INDEX('[1]Match Report'!$A$2:$BC$253,MATCH(LEFT(D31,LEN(D31)-1),'[1]Match Report'!$AL$2:$AL$253,0),7) -> #N/A | F31: =IFERROR(IF(VLOOKUP($D31,'E2 Data Mapping'!$D$5:$D$73,MATCH('7.4'!F$5,'E2 Data Mapping'!$D$5:$D$5,0),FALSE)=0,"",VLOOKUP($D31,'E2 Data Mapping'!$D$5:$D$73,MATCH('7.4'!F$5,'E2 Data Mapping'!$D$5:$D$5,0),FALSE)),"") | H31: TBC | I31: =IFERROR(IF(VLOOKUP($D31,'E2 Data Mapping'!$D$5:$D$73,MATCH('7.4'!I$5,'E2 Data Mapping'!$D$5:$D$5,0),FALSE)=0,"",VLOOKUP($D31,'E2 Data Mapping'!$D$5:$D$73,MATCH('7.4'!I$5,'E2 Data Mapping'!$D$5:$D$5,0),FALSE)),"")
B32: Tax Type | C32: C | D32: ENT-TTY-CODE | E32: =INDEX('[1]Match Report'!$A$2:$BC$253,MATCH(LEFT(D32,LEN(D32)-1),'[1]Match Report'!$AL$2:$AL$253,0),7) -> #N/A | F32: =IFERROR(IF(VLOOKUP($D32,'E2 Data Mapping'!$D$5:$D$73,MATCH('7.4'!F$5,'E2 Data Mapping'!$D$5:$D$5,0),FALSE)=0,"",VLOOKUP($D32,'E2 Data Mapping'!$D$5:$D$73,MATCH('7.4'!F$5,'E2 Data Mapping'!$D$5:$D$5,0),FALSE)),"") | H32: =IFERROR(IF(VLOOKUP($D32,'E2 Data Mapping'!$D$5:$D$73,MATCH('7.4'!H$5,'E2 Data Mapping'!$D$5:$D$5,0),FALSE)=0,"",VLOOKUP($D32,'E2 Data Mapping'!$D$5:$D$73,MATCH('7.4'!H$5,'E2 Data Mapping'!$D$5:$D$5,0),FALSE)),"") | I32: =IFERROR(IF(VLOOKUP($D32,'E2 Data Mapping'!$D$5:$D$73,MATCH('7.4'!I$5,'E2 Data Mapping'!$D$5:$D$5,0),FALSE)=0,"",VLOOKUP($D32,'E2 Data Mapping'!$D$5:$D$73,MATCH('7.4'!I$5,'E2 Data Mapping'!$D$5:$D$5,0),FALSE)),"")
B33: MOP | C33: D | D33: ENT-MOP-CODE | E33: =INDEX('[1]Match Report'!$A$2:$BC$253,MATCH(LEFT(D33,LEN(D33)-1),'[1]Match Report'!$AL$2:$AL$253,0),7) -> #N/A | F33: =IFERROR(IF(VLOOKUP($D33,'E2 Data Mapping'!$D$5:$D$73,MATCH('7.4'!F$5,'E2 Data Mapping'!$D$5:$D$5,0),FALSE)=0,"",VLOOKUP($D33,'E2 Data Mapping'!$D$5:$D$73,MATCH('7.4'!F$5,'E2 Data Mapping'!$D$5:$D$5,0),FALSE)),"") | H33: =IFERROR(IF(VLOOKUP($D33,'E2 Data Mapping'!$D$5:$D$73,MATCH('7.4'!H$5,'E2 Data Mapping'!$D$5:$D$5,0),FALSE)=0,"",VLOOKUP($D33,'E2 Data Mapping'!$D$5:$D$73,MATCH('7.4'!H$5,'E2 Data Mapping'!$D$5:$D$5,0),FALSE)),"") | I33: =IFERROR(IF(VLOOKUP($D33,'E2 Data Mapping'!$D$5:$D$73,MATCH('7.4'!I$5,'E2 Data Mapping'!$D$5:$D$5,0),FALSE)=0,"",VLOOKUP($D33,'E2 Data Mapping'!$D$5:$D$73,MATCH('7.4'!I$5,'E2 Data Mapping'!$D$5:$D$5,0),FALSE)),"")
B34: Previous Tax Amount | C34: E | D34: PREV-ENT-TOT-REV | E34: =INDEX('[1]Match Report'!$A$2:$BC$253,MATCH(LEFT(D34,LEN(D34)-1),'[1]Match Report'!$AL$2:$AL$253,0),7) -> #N/A | F34: N/A | H34: =IFERROR(IF(VLOOKUP($D34,'E2 Data Mapping'!$D$5:$D$73,MATCH('7.4'!H$5,'E2 Data Mapping'!$D$5:$D$5,0),FALSE)=0,"",VLOOKUP($D34,'E2 Data Mapping'!$D$5:$D$73,MATCH('7.4'!H$5,'E2 Data Mapping'!$D$5:$D$5,0),FALSE)),"") | I34: No equivalent currently in CDS
B35: Current Tax Amount | C35: F | D35: CURR-ENT-TOT-REV | E35: =INDEX('[1]Match Report'!$A$2:$BC$253,MATCH(LEFT(D35,LEN(D35)-1),'[1]Match Report'!$AL$2:$AL$253,0),7) -> #N/A | F35: 4/6 | H35: =IFERROR(IF(VLOOKUP($D35,'E2 Data Mapping'!$D$5:$D$73,MATCH('7.4'!H$5,'E2 Data Mapping'!$D$5:$D$5,0),FALSE)=0,"",VLOOKUP($D35,'E2 Data Mapping'!$D$5:$D$73,MATCH('7.4'!H$5,'E2 Data Mapping'!$D$5:$D$5,0),FALSE)),"") | I35: =IFERROR(IF(VLOOKUP($D35,'E2 Data Mapping'!$D$5:$D$73,MATCH('7.4'!I$5,'E2 Data Mapping'!$D$5:$D$5,0),FALSE)=0,"",VLOOKUP($D35,'E2 Data Mapping'!$D$5:$D$73,MATCH('7.4'!I$5,'E2 Data Mapping'!$D$5:$D$5,0),FALSE)),"")
B36: Consignment Amends | C36: G | D36: AMD-HDR-LABEL | E36: =INDEX('[1]Match Report'!$A$2:$BC$253,MATCH(LEFT(D36,LEN(D36)-1),'[1]Match Report'!$AL$2:$AL$253,0),7) -> #N/A | F36: - | H36: =IFERROR(IF(VLOOKUP($D36,'E2 Data Mapping'!$D$5:$D$73,MATCH('7.4'!H$5,'E2 Data Mapping'!$D$5:$D$5,0),FALSE)=0,"",VLOOKUP($D36,'E2 Data Mapping'!$D$5:$D$73,MATCH('7.4'!H$5,'E2 Data Mapping'!$D$5:$D$5,0),FALSE)),"") | I36: No equivalent found in Technical Completion Matrix
B37: From | C37: H | D37: HDR-PREV-QTY | E37: =INDEX('[1]Match Report'!$A$2:$BC$253,MATCH(LEFT(D37,LEN(D37)-1),'[1]Match Report'!$AL$2:$AL$253,0),7) -> #N/A | F37: - | H37: =IFERROR(IF(VLOOKUP($D37,'E2 Data Mapping'!$D$5:$D$73,MATCH('7.4'!H$5,'E2 Data Mapping'!$D$5:$D$5,0),FALSE)=0,"",VLOOKUP($D37,'E2 Data Mapping'!$D$5:$D$73,MATCH('7.4'!H$5,'E2 Data Mapping'!$D$5:$D$5,0),FALSE)),"") | I37: No equivalent found in Technical Completion Matrix
C38: H | D38: HDR-PREV-VAL | E38: =INDEX('[1]Match Report'!$A$2:$BC$253,MATCH(LEFT(D38,LEN(D38)-1),'[1]Match Report'!$AL$2:$AL$253,0),7) -> #N/A | F38: - | H38: =IFERROR(IF(VLOOKUP($D38,'E2 Data Mapping'!$D$5:$D$73,MATCH('7.4'!H$5,'E2 Data Mapping'!$D$5:$D$5,0),FALSE)=0,"",VLOOKUP($D38,'E2 Data Mapping'!$D$5:$D$73,MATCH('7.4'!H$5,'E2 Data Mapping'!$D$5:$D$5,0),FALSE)),"") | I38: No equivalent found in Technical Completion Matrix
C39: H | D39: HDR-PREV-INTGR | E39: =INDEX('[1]Match Report'!$A$2:$BC$253,MATCH(LEFT(D39,LEN(D39)-1),'[1]Match Report'!$AL$2:$AL$253,0),7) -> #N/A | F39: - | H39: =IFERROR(IF(VLOOKUP($D39,'E2 Data Mapping'!$D$5:$D$73,MATCH('7.4'!H$5,'E2 Data Mapping'!$D$5:$D$5,0),FALSE)=0,"",VLOOKUP($D39,'E2 Data Mapping'!$D$5:$D$73,MATCH('7.4'!H$5,'E2 Data Mapping'!$D$5:$D$5,0),FALSE)),"") | I39: No equivalent found in Technical Completion Matrix
C40: H | D40: HDR-PREV-CHARS | E40: =INDEX('[1]Match Report'!$A$2:$BC$253,MATCH(LEFT(D40,LEN(D40)-1),'[1]Match Report'!$AL$2:$AL$253,0),7) -> #N/A | F40: - | H40: =IFERROR(IF(VLOOKUP($D40,'E2 Data Mapping'!$D$5:$D$73,MATCH('7.4'!H$5,'E2 Data Mapping'!$D$5:$D$5,0),FALSE)=0,"",VLOOKUP($D40,'E2 Data Mapping'!$D$5:$D$73,MATCH('7.4'!H$5,'E2 Data Mapping'!$D$5:$D$5,0),FALSE)),"") | I40: No equivalent found in Technical Completion Matrix
B41: To | C41: I | D41: HDR-CURR-QTY | E41: =INDEX('[1]Match Report'!$A$2:$BC$253,MATCH(LEFT(D41,LEN(D41)-1),'[1]Match Report'!$AL$2:$AL$253,0),7) -> #N/A | F41: - | H41: =IFERROR(IF(VLOOKUP($D41,'E2 Data Mapping'!$D$5:$D$73,MATCH('7.4'!H$5,'E2 Data Mapping'!$D$5:$D$5,0),FALSE)=0,"",VLOOKUP($D41,'E2 Data Mapping'!$D$5:$D$73,MATCH('7.4'!H$5,'E2 Data Mapping'!$D$5:$D$5,0),FALSE)),"") | I41: No equivalent found in Technical Completion Matrix
C42: I | D42: HDR-CURR-VAL | E42: =INDEX('[1]Match Report'!$A$2:$BC$253,MATCH(LEFT(D42,LEN(D42)-1),'[1]Match Report'!$AL$2:$AL$253,0),7) -> #N/A | F42: - | H42: =IFERROR(IF(VLOOKUP($D42,'E2 Data Mapping'!$D$5:$D$73,MATCH('7.4'!H$5,'E2 Data Mapping'!$D$5:$D$5,0),FALSE)=0,"",VLOOKUP($D42,'E2 Data Mapping'!$D$5:$D$73,MATCH('7.4'!H$5,'E2 Data Mapping'!$D$5:$D$5,0),FALSE)),"") | I42: No equivalent found in Technical Completion Matrix
C43: I | D43: HDR-CURR-INTGR | E43: =INDEX('[1]Match Report'!$A$2:$BC$253,MATCH(LEFT(D43,LEN(D43)-1),'[1]Match Report'!$AL$2:$AL$253,0),7) -> #N/A | F43: - | H43: =IFERROR(IF(VLOOKUP($D43,'E2 Data Mapping'!$D$5:$D$73,MATCH('7.4'!H$5,'E2 Data Mapping'!$D$5:$D$5,0),FALSE)=0,"",VLOOKUP($D43,'E2 Data Mapping'!$D$5:$D$73,MATCH('7.4'!H$5,'E2 Data Mapping'!$D$5:$D$5,0),FALSE)),"") | I43: No equivalent found in Technical Completion Matrix
...

Sheet 7.5
B2: Number | C2: Description | N2: CHIEF IMPORTS Report Name | O2: CDS Notif Equivalent
B3: 7.5 | C3: =VLOOKUP(B3,#REF!,2,FALSE) -> #REF! | N3: E8 | O3: =VLOOKUP(N3,#REF!,2,FALSE) -> #REF!
B5: Field Name | C5: Field | D5: CHIEF EDIFACT | E5: Lookup from Data Arch | F5: CDS Decln. D.E. | G5: DMS Notification Element | H5: System Generated? | I5: Notes
B6: Entry | C6: a | D6: ENT-REF | E6: =INDEX('[1]Match Report'!$A$2:$BC$253,MATCH(LEFT(D6,LEN(D6)-1),'[1]Match Report'!$AL$2:$AL$253,0),7) -> #N/A | F6: =IFERROR(IF(VLOOKUP($D6,'E2 Data Mapping'!$D$5:$D$73,MATCH(F$5,'E2 Data Mapping'!$D$5:$D$5,0),FALSE)=0,"",VLOOKUP($D6,'E2 Data Mapping'!$D$5:$D$73,MATCH(F$5,'E2 Data Mapping'!$D$5:$D$5,0),FALSE)),"") | H6: =IFERROR(IF(VLOOKUP($D6,'E2 Data Mapping'!$D$5:$D$73,MATCH(H$5,'E2 Data Mapping'!$D$5:$D$5,0),FALSE)=0,"",VLOOKUP($D6,'E2 Data Mapping'!$D$5:$D$73,MATCH(H$5,'E2 Data Mapping'!$D$5:$D$5,0),FALSE)),"") | I6: =IFERROR(IF(VLOOKUP($D6,'E2 Data Mapping'!$D$5:$D$73,MATCH(I$5,'E2 Data Mapping'!$D$5:$D$5,0),FALSE)=0,"",VLOOKUP($D6,'E2 Data Mapping'!$D$5:$D$73,MATCH(I$5,'E2 Data Mapping'!$D$5:$D$5,0),FALSE)),"")
B7: Entry | C7: b | D7: ENT-TYPE | E7: =INDEX('[1]Match Report'!$A$2:$BC$253,MATCH(LEFT(D7,LEN(D7)-1),'[1]Match Report'!$AL$2:$AL$253,0),7) -> #N/A | F7: =IFERROR(IF(VLOOKUP($D7,'E2 Data Mapping'!$D$5:$D$73,MATCH(F$5,'E2 Data Mapping'!$D$5:$D$5,0),FALSE)=0,"",VLOOKUP($D7,'E2 Data Mapping'!$D$5:$D$73,MATCH(F$5,'E2 Data Mapping'!$D$5:$D$5,0),FALSE)),"") | H7: =IFERROR(IF(VLOOKUP($D7,'E2 Data Mapping'!$D$5:$D$73,MATCH(H$5,'E2 Data Mapping'!$D$5:$D$5,0),FALSE)=0,"",VLOOKUP($D7,'E2 Data Mapping'!$D$5:$D$73,MATCH(H$5,'E2 Data Mapping'!$D$5:$D$5,0),FALSE)),"") | I7: =IFERROR(IF(VLOOKUP($D7,'E2 Data Mapping'!$D$5:$D$73,MATCH(I$5,'E2 Data Mapping'!$D$5:$D$5,0),FALSE)=0,"",VLOOKUP($D7,'E2 Data Mapping'!$D$5:$D$73,MATCH(I$5,'E2 Data Mapping'!$D$5:$D$5,0),FALSE)),"")
B8: Version | C8: c | D8: ENT-VER-NO | E8: =INDEX('[1]Match Report'!$A$2:$BC$253,MATCH(LEFT(D8,LEN(D8)-1),'[1]Match Report'!$AL$2:$AL$253,0),7) -> #N/A | F8: =IFERROR(IF(VLOOKUP($D8,'E2 Data Mapping'!$D$5:$D$73,MATCH(F$5,'E2 Data Mapping'!$D$5:$D$5,0),FALSE)=0,"",VLOOKUP($D8,'E2 Data Mapping'!$D$5:$D$73,MATCH(F$5,'E2 Data Mapping'!$D$5:$D$5,0),FALSE)),"") | H8: =IFERROR(IF(VLOOKUP($D8,'E2 Data Mapping'!$D$5:$D$73,MATCH(H$5,'E2 Data Mapping'!$D$5:$D$5,0),FALSE)=0,"",VLOOKUP($D8,'E2 Data Mapping'!$D$5:$D$73,MATCH(H$5,'E2 Data Mapping'!$D$5:$D$5,0),FALSE)),"") | I8: =IFERROR(IF(VLOOKUP($D8,'E2 Data Mapping'!$D$5:$D$73,MATCH(I$5,'E2 Data Mapping'!$D$5:$D$5,0),FALSE)=0,"",VLOOKUP($D8,'E2 Data Mapping'!$D$5:$D$73,MATCH(I$5,'E2 Data Mapping'!$D$5:$D$5,0),FALSE)),"")
B9: Route | C9: d | D9: ROE | E9: =INDEX('[1]Match Report'!$A$2:$BC$253,MATCH(LEFT(D9,LEN(D9)-1),'[1]Match Report'!$AL$2:$AL$253,0),7) -> #N/A | F9: =IFERROR(IF(VLOOKUP($D9,'E2 Data Mapping'!$D$5:$D$73,MATCH(F$5,'E2 Data Mapping'!$D$5:$D$5,0),FALSE)=0,"",VLOOKUP($D9,'E2 Data Mapping'!$D$5:$D$73,MATCH(F$5,'E2 Data Mapping'!$D$5:$D$5,0),FALSE)),"") | H9: =IFERROR(IF(VLOOKUP($D9,'E2 Data Mapping'!$D$5:$D$73,MATCH(H$5,'E2 Data Mapping'!$D$5:$D$5,0),FALSE)=0,"",VLOOKUP($D9,'E2 Data Mapping'!$D$5:$D$73,MATCH(H$5,'E2 Data Mapping'!$D$5:$D$5,0),FALSE)),"") | I9: =IFERROR(IF(VLOOKUP($D9,'E2 Data Mapping'!$D$5:$D$73,MATCH(I$5,'E2 Data Mapping'!$D$5:$D$5,0),FALSE)=0,"",VLOOKUP($D9,'E2 Data Mapping'!$D$5:$D$73,MATCH(I$5,'E2 Data Mapping'!$D$5:$D$5,0),FALSE)),"")
B10: at | C10: e | D10: GDS-EPU-NO | E10: =INDEX('[1]Match Report'!$A$2:$BC$253,MATCH(LEFT(D10,LEN(D10)-1),'[1]Match Report'!$AL$2:$AL$253,0),7) -> #N/A | F10: =IFERROR(IF(VLOOKUP($D10,'E2 Data Mapping'!$D$5:$D$73,MATCH(F$5,'E2 Data Mapping'!$D$5:$D$5,0),FALSE)=0,"",VLOOKUP($D10,'E2 Data Mapping'!$D$5:$D$73,MATCH(F$5,'E2 Data Mapping'!$D$5:$D$5,0),FALSE)),"") | H10: =IFERROR(IF(VLOOKUP($D10,'E2 Data Mapping'!$D$5:$D$73,MATCH(H$5,'E2 Data Mapping'!$D$5:$D$5,0),FALSE)=0,"",VLOOKUP($D10,'E2 Data Mapping'!$D$5:$D$73,MATCH(H$5,'E2 Data Mapping'!$D$5:$D$5,0),FALSE)),"") | I10: =IFERROR(IF(VLOOKUP($D10,'E2 Data Mapping'!$D$5:$D$73,MATCH(I$5,'E2 Data Mapping'!$D$5:$D$5,0),FALSE)=0,"",VLOOKUP($D10,'E2 Data Mapping'!$D$5:$D$73,MATCH(I$5,'E2 Data Mapping'!$D$5:$D$5,0),FALSE)),"")
B11: at | C11: e | D11: + GDS-EPS-ID | E11: =INDEX('[1]Match Report'!$A$2:$BC$253,MATCH(LEFT(D11,LEN(D11)-1),'[1]Match Report'!$AL$2:$AL$253,0),7) -> #N/A | F11: =IFERROR(IF(VLOOKUP($D11,'E2 Data Mapping'!$D$5:$D$73,MATCH(F$5,'E2 Data Mapping'!$D$5:$D$5,0),FALSE)=0,"",VLOOKUP($D11,'E2 Data Mapping'!$D$5:$D$73,MATCH(F$5,'E2 Data Mapping'!$D$5:$D$5,0),FALSE)),"") | H11: =IFERROR(IF(VLOOKUP($D11,'E2 Data Mapping'!$D$5:$D$73,MATCH(H$5,'E2 Data Mapping'!$D$5:$D$5,0),FALSE)=0,"",VLOOKUP($D11,'E2 Data Mapping'!$D$5:$D$73,MATCH(H$5,'E2 Data Mapping'!$D$5:$D$5,0),FALSE)),"") | I11: =IFERROR(IF(VLOOKUP($D11,'E2 Data Mapping'!$D$5:$D$73,MATCH(I$5,'E2 Data Mapping'!$D$5:$D$5,0),FALSE)=0,"",VLOOKUP($D11,'E2 Data Mapping'!$D$5:$D$73,MATCH(I$5,'E2 Data Mapping'!$D$5:$D$5,0),FALSE)),"")
B12: status | C12: f | D12: ICS | E12: =INDEX('[1]Match Report'!$A$2:$BC$253,MATCH(LEFT(D12,LEN(D12)-1),'[1]Match Report'!$AL$2:$AL$253,0),7) -> #N/A | F12: =IFERROR(IF(VLOOKUP($D12,'E2 Data Mapping'!$D$5:$D$73,MATCH(F$5,'E2 Data Mapping'!$D$5:$D$5,0),FALSE)=0,"",VLOOKUP($D12,'E2 Data Mapping'!$D$5:$D$73,MATCH(F$5,'E2 Data Mapping'!$D$5:$D$5,0),FALSE)),"") | H12: =IFERROR(IF(VLOOKUP($D12,'E2 Data Mapping'!$D$5:$D$73,MATCH(H$5,'E2 Data Mapping'!$D$5:$D$5,0),FALSE)=0,"",VLOOKUP($D12,'E2 Data Mapping'!$D$5:$D$73,MATCH(H$5,'E2 Data Mapping'!$D$5:$D$5,0),FALSE)),"") | I12: =IFERROR(IF(VLOOKUP($D12,'E2 Data Mapping'!$D$5:$D$73,MATCH(I$5,'E2 Data Mapping'!$D$5:$D$5,0),FALSE)=0,"",VLOOKUP($D12,'E2 Data Mapping'!$D$5:$D$73,MATCH(I$5,'E2 Data Mapping'!$D$5:$D$5,0),FALSE)),"")
B13: Entry Accepted | C13: g | D13: ACPTNC-DTM | E13: =INDEX('[1]Match Report'!$A$2:$BC$253,MATCH(LEFT(D13,LEN(D13)-1),'[1]Match Report'!$AL$2:$AL$253,0),7) -> #N/A | F13: =IFERROR(IF(VLOOKUP($D13,'E2 Data Mapping'!$D$5:$D$73,MATCH(F$5,'E2 Data Mapping'!$D$5:$D$5,0),FALSE)=0,"",VLOOKUP($D13,'E2 Data Mapping'!$D$5:$D$73,MATCH(F$5,'E2 Data Mapping'!$D$5:$D$5,0),FALSE)),"") | H13: =IFERROR(IF(VLOOKUP($D13,'E2 Data Mapping'!$D$5:$D$73,MATCH(H$5,'E2 Data Mapping'!$D$5:$D$5,0),FALSE)=0,"",VLOOKUP($D13,'E2 Data Mapping'!$D$5:$D$73,MATCH(H$5,'E2 Data Mapping'!$D$5:$D$5,0),FALSE)),"") | I13: =IFERROR(IF(VLOOKUP($D13,'E2 Data Mapping'!$D$5:$D$73,MATCH(I$5,'E2 Data Mapping'!$D$5:$D$5,0),FALSE)=0,"",VLOOKUP($D13,'E2 Data Mapping'!$D$5:$D$73,MATCH(I$5,'E2 Data Mapping'!$D$5:$D$5,0),FALSE)),"")
B14: Office | C14: h | D14: ACPTNC-EPU-NO | E14: =INDEX('[1]Match Report'!$A$2:$BC$253,MATCH(LEFT(D14,LEN(D14)-1),'[1]Match Report'!$AL$2:$AL$253,0),7) -> #N/A | F14: =IFERROR(IF(VLOOKUP($D14,'E2 Data Mapping'!$D$5:$D$73,MATCH(F$5,'E2 Data Mapping'!$D$5:$D$5,0),FALSE)=0,"",VLOOKUP($D14,'E2 Data Mapping'!$D$5:$D$73,MATCH(F$5,'E2 Data Mapping'!$D$5:$D$5,0),FALSE)),"") | H14: =IFERROR(IF(VLOOKUP($D14,'E2 Data Mapping'!$D$5:$D$73,MATCH(H$5,'E2 Data Mapping'!$D$5:$D$5,0),FALSE)=0,"",VLOOKUP($D14,'E2 Data Mapping'!$D$5:$D$73,MATCH(H$5,'E2 Data Mapping'!$D$5:$D$5,0),FALSE)),"") | I14: =IFERROR(IF(VLOOKUP($D14,'E2 Data Mapping'!$D$5:$D$73,MATCH(I$5,'E2 Data Mapping'!$D$5:$D$5,0),FALSE)=0,"",VLOOKUP($D14,'E2 Data Mapping'!$D$5:$D$73,MATCH(I$5,'E2 Data Mapping'!$D$5:$D$5,0),FALSE)),"")
B15: Office | C15: h | D15: + ACPTNC-EPS-ID | E15: =INDEX('[1]Match Report'!$A$2:$BC$253,MATCH(LEFT(D15,LEN(D15)-1),'[1]Match Report'!$AL$2:$AL$253,0),7) -> #N/A | F15: =IFERROR(IF(VLOOKUP($D15,'E2 Data Mapping'!$D$5:$D$73,MATCH(F$5,'E2 Data Mapping'!$D$5:$D$5,0),FALSE)=0,"",VLOOKUP($D15,'E2 Data Mapping'!$D$5:$D$73,MATCH(F$5,'E2 Data Mapping'!$D$5:$D$5,0),FALSE)),"") | H15: =IFERROR(IF(VLOOKUP($D15,'E2 Data Mapping'!$D$5:$D$73,MATCH(H$5,'E2 Data Mapping'!$D$5:$D$5,0),FALSE)=0,"",VLOOKUP($D15,'E2 Data Mapping'!$D$5:$D$73,MATCH(H$5,'E2 Data Mapping'!$D$5:$D$5,0),FALSE)),"") | I15: =IFERROR(IF(VLOOKUP($D15,'E2 Data Mapping'!$D$5:$D$73,MATCH(I$5,'E2 Data Mapping'!$D$5:$D$5,0),FALSE)=0,"",VLOOKUP($D15,'E2 Data Mapping'!$D$5:$D$73,MATCH(I$5,'E2 Data Mapping'!$D$5:$D$5,0),FALSE)),"")
B16: Declarant Id | C16: j | D16: DECLT-TID | E16: =INDEX('[1]Match Report'!$A$2:$BC$253,MATCH(LEFT(D16,LEN(D16)-1),'[1]Match Report'!$AL$2:$AL$253,0),7) -> #N/A | F16: =IFERROR(IF(VLOOKUP($D16,'E2 Data Mapping'!$D$5:$D$73,MATCH(F$5,'E2 Data Mapping'!$D$5:$D$5,0),FALSE)=0,"",VLOOKUP($D16,'E2 Data Mapping'!$D$5:$D$73,MATCH(F$5,'E2 Data Mapping'!$D$5:$D$5,0),FALSE)),"") | H16: =IFERROR(IF(VLOOKUP($D16,'E2 Data Mapping'!$D$5:$D$73,MATCH(H$5,'E2 Data Mapping'!$D$5:$D$5,0),FALSE)=0,"",VLOOKUP($D16,'E2 Data Mapping'!$D$5:$D$73,MATCH(H$5,'E2 Data Mapping'!$D$5:$D$5,0),FALSE)),"") | I16: =IFERROR(IF(VLOOKUP($D16,'E2 Data Mapping'!$D$5:$D$73,MATCH(I$5,'E2 Data Mapping'!$D$5:$D$5,0),FALSE)=0,"",VLOOKUP($D16,'E2 Data Mapping'!$D$5:$D$73,MATCH(I$5,'E2 Data Mapping'!$D$5:$D$5,0),FALSE)),"")
B17: Submitting TURN | C17: k | D17: SUBMIT-TURN | E17: =INDEX('[1]Match Report'!$A$2:$BC$253,MATCH(LEFT(D17,LEN(D17)-1),'[1]Match Report'!$AL$2:$AL$253,0),7) -> #N/A | F17: =IFERROR(IF(VLOOKUP($D17,'E2 Data Mapping'!$D$5:$D$73,MATCH(F$5,'E2 Data Mapping'!$D$5:$D$5,0),FALSE)=0,"",VLOOKUP($D17,'E2 Data Mapping'!$D$5:$D$73,MATCH(F$5,'E2 Data Mapping'!$D$5:$D$5,0),FALSE)),"") | H17: =IFERROR(IF(VLOOKUP($D17,'E2 Data Mapping'!$D$5:$D$73,MATCH(H$5,'E2 Data Mapping'!$D$5:$D$5,0),FALSE)=0,"",VLOOKUP($D17,'E2 Data Mapping'!$D$5:$D$73,MATCH(H$5,'E2 Data Mapping'!$D$5:$D$5,0),FALSE)),"") | I17: =IFERROR(IF(VLOOKUP($D17,'E2 Data Mapping'!$D$5:$D$73,MATCH(I$5,'E2 Data Mapping'!$D$5:$D$5,0),FALSE)=0,"",VLOOKUP($D17,'E2 Data Mapping'!$D$5:$D$73,MATCH(I$5,'E2 Data Mapping'!$D$5:$D$5,0),FALSE)),"")
... B30: Total Packages | C30: u | D30: TOT-PKGS | E30: =INDEX('[1]Match Report'!$A$2:$BC$253,MATCH(LEFT(D30,LEN(D30)-1),'[1]Match Report'!$AL$2:$AL$253,0),7) -> 6/18 | F30: =IFERROR(IF(VLOOKUP($D30,'E2 Data Mapping'!$D$5:$D$73,MATCH(F$5,'E2 Data Mapping'!$D$5:$D$5,0),FALSE)=0,"",VLOOKUP($D30,'E2 Data Mapping'!$D$5:$D$73,MATCH(F$5,'E2 Data Mapping'!$D$5:$D$5,0),FALSE)),"") | H30: =IFERROR(IF(VLOOKUP($D30,'E2 Data Mapping'!$D$5:$D$73,MATCH(H$5,'E2 Data Mapping'!$D$5:$D$5,0),FALSE)=0,"",VLOOKUP($D30,'E2 Data Mapping'!$D$5:$D$73,MATCH(H$5,'E2 Data Mapping'!$D$5:$D$5,0),FALSE)),"") | I30: =IFERROR(IF(VLOOKUP($D30,'E2 Data Mapping'!$D$5:$D$73,MATCH(I$5,'E2 Data Mapping'!$D$5:$D$5,0),FALSE)=0,"",VLOOKUP($D30,'E2 Data Mapping'!$D$5:$D$73,MATCH(I$5,'E2 Data Mapping'!$D$5:$D$5,0),FALSE)),"")
B31: Authorised Premises Name | C31: A | D31: PREM-NAME | E31: =INDEX('[1]Match Report'!$A$2:$BC$253,MATCH(LEFT(D31,LEN(D31)-1),'[1]Match Report'!$AL$2:$AL$253,0),7) -> #N/A | H31: TBC
B32: Authorised Premises ID | C32: B | D32: PREM-ID | E32: =INDEX('[1]Match Report'!$A$2:$BC$253,MATCH(LEFT(D32,LEN(D32)-1),'[1]Match Report'!$AL$2:$AL$253,0),7) -> 2/7 | F32: 2/7 | H32: TBC
B33: Authorised Premises Address | C33: C | D33: PREM-STREET | E33: =INDEX('[1]Match Report'!$A$2:$BC$253,MATCH(LEFT(D33,LEN(D33)-1),'[1]Match Report'!$AL$2:$AL$253,0),7) -> #N/A | H33: TBC
C34: C | D34: + PREM-STREET2 | E34: =INDEX('[1]Match Report'!$A$2:$BC$253,MATCH(LEFT(D34,LEN(D34)-1),'[1]Match Report'!$AL$2:$AL$253,0),7) -> #N/A | H34: TBC
C35: C | D35: + PREM-STREET3 | E35: =INDEX('[1]Match Report'!$A$2:$BC$253,MATCH(LEFT(D35,LEN(D35)-1),'[1]Match Report'!$AL$2:$AL$253,0),7) -> #N/A | H35: TBC
C36: C | D36: + PREM-STREET4 | E36: =INDEX('[1]Match Report'!$A$2:$BC$253,MATCH(LEFT(D36,LEN(D36)-1),'[1]Match Report'!$AL$2:$AL$253,0),7) -> #N/A | H36: TBC
C37: D | D37: PREM-CITY | E37: =INDEX('[1]Match Report'!$A$2:$BC$253,MATCH(LEFT(D37,LEN(D37)-1),'[1]Match Report'!$AL$2:$AL$253,0),7) -> #N/A | H37: TBC
C38: E | D38: PREM-POSTCODE | E38: =INDEX('[1]Match Report'!$A$2:$BC$253,MATCH(LEFT(D38,LEN(D38)-1),'[1]Match Report'!$AL$2:$AL$253,0),7) -> #N/A | H38: TBC
C39: F | D39: PREM-CNTRY | E39: =INDEX('[1]Match Report'!$A$2:$BC$253,MATCH(LEFT(D39,LEN(D39)-1),'[1]Match Report'!$AL$2:$AL$253,0),7) -> #N/A | H39: TBC
B40: Supervising Office Name | C40: G | D40: SPOFF-NAME | E40: =INDEX('[1]Match Report'!$A$2:$BC$253,MATCH(LEFT(D40,LEN(D40)-1),'[1]Match Report'!$AL$2:$AL$253,0),7) -> #N/A | H40: TBC
B41: Supervising Office ID | C41: H | D41: SPOFF-CODE | E41: =INDEX('[1]Match Report'!$A$2:$BC$253,MATCH(LEFT(D41,LEN(D41)-1),'[1]Match Report'!$AL$2:$AL$253,0),7) -> #N/A | H41: TBC
B42: Supervising Office Address | C42: J | D42: SPOFF-STREET | E42: =INDEX('[1]Match Report'!$A$2:$BC$253,MATCH(LEFT(D42,LEN(D42)-1),'[1]Match Report'!$AL$2:$AL$253,0),7) -> #N/A | H42: TBC
C43: J | D43: + SPOFF-STREET2 | E43: =INDEX('[1]Match Report'!$A$2:$BC$253,MATCH(LEFT(D43,LEN(D43)-1),'[1]Match Report'!$AL$2:$AL$253,0),7) -> #N/A | H43: TBC
C44: J | D44: + SPOFF-STREET3 | E44: =INDEX('[1]Match Report'!$A$2:$BC$253,MATCH(LEFT(D44,LEN(D44)-1),'[1]Match Report'!$AL$2:$AL$253,0),7) -> #N/A | H44: TBC
C45: J | D45: + SPOFF-STREET4 | E45: =INDEX('[1]Match Report'!$A$2:$BC$253,MATCH(LEFT(D45,LEN(D45)-1),'[1]Match Report'!$AL$2:$AL$253,0),7) -> #N/A | H45: TBC
C46: K | D46: SPOFF-CITY | E46: =INDEX('[1]Match Report'!$A$2:$BC$253,MATCH(LEFT(D46,LEN(D46)-1),'[1]Match Report'!$AL$2:$AL$253,0),7) -> #N/A | H46: TBC
C47: L | D47: SPOFF-POSTCODE | E47: =INDEX('[1]Match Report'!$A$2:$BC$253,MATCH(LEFT(D47,LEN(D47)-1),'[1]Match Report'!$AL$2:$AL$253,0),7) -> #N/A | H47: TBC
C48: M | D48: SPOFF-CNTRY | E48: =INDEX('[1]Match Report'!$A$2:$BC$253,MATCH(LEFT(D48,LEN(D48)-1),'[1]Match Report'!$AL$2:$AL$253,0),7) -> #N/A | H48: TBC

Sheet 7.6
B2: Number | C2: Description | N2: CHIEF IMPORTS Report Name | O2: CDS Notif Equivalent
B3: 7.6 | C3: =VLOOKUP(B3,#REF!,2,FALSE) -> #REF! | N3: E9 | O3: =VLOOKUP(N3,#REF!,2,FALSE) -> #REF!
B5: Field Name | C5: Field | D5: CHIEF EDIFACT | E5: Lookup from Data Arch | F5: CDS Decln. D.E. | G5: DMS Notification Element | H5: System Generated? | I5: Notes
B6: Entry | C6: a | D6: ENT-REF | E6: =INDEX('[1]Match Report'!$A$2:$BC$253,MATCH(LEFT(D6,LEN(D6)-1),'[1]Match Report'!$AL$2:$AL$253,0),7) -> #N/A | F6: =IFERROR(IF(VLOOKUP($D6,'E2 Data Mapping'!$D$5:$D$73,MATCH(F$5,'E2 Data Mapping'!$D$5:$D$5,0),FALSE)=0,"",VLOOKUP($D6,'E2 Data Mapping'!$D$5:$D$73,MATCH(F$5,'E2 Data Mapping'!$D$5:$D$5,0),FALSE)),"") | H6: =IFERROR(IF(VLOOKUP($D6,'E2 Data Mapping'!$D$5:$D$73,MATCH(H$5,'E2 Data Mapping'!$D$5:$D$5,0),FALSE)=0,"",VLOOKUP($D6,'E2 Data Mapping'!$D$5:$D$73,MATCH(H$5,'E2 Data Mapping'!$D$5:$D$5,0),FALSE)),"") | I6: =IFERROR(IF(VLOOKUP($D6,'E2 Data Mapping'!$D$5:$D$73,MATCH(I$5,'E2 Data Mapping'!$D$5:$D$5,0),FALSE)=0,"",VLOOKUP($D6,'E2 Data Mapping'!$D$5:$D$73,MATCH(I$5,'E2 Data Mapping'!$D$5:$D$5,0),FALSE)),"")
B7: Entry | C7: b | D7: ENT-TYPE | E7: =INDEX('[1]Match Report'!$A$2:$BC$253,MATCH(LEFT(D7,LEN(D7)-1),'[1]Match Report'!$AL$2:$AL$253,0),7) -> #N/A | F7: =IFERROR(IF(VLOOKUP($D7,'E2 Data Mapping'!$D$5:$D$73,MATCH(F$5,'E2 Data Mapping'!$D$5:$D$5,0),FALSE)=0,"",VLOOKUP($D7,'E2 Data Mapping'!$D$5:$D$73,MATCH(F$5,'E2 Data Mapping'!$D$5:$D$5,0),FALSE)),"") | H7: =IFERROR(IF(VLOOKUP($D7,'E2 Data Mapping'!$D$5:$D$73,MATCH(H$5,'E2 Data Mapping'!$D$5:$D$5,0),FALSE)=0,"",VLOOKUP($D7,'E2 Data Mapping'!$D$5:$D$73,MATCH(H$5,'E2 Data Mapping'!$D$5:$D$5,0),FALSE)),"") | I7: =IFERROR(IF(VLOOKUP($D7,'E2 Data Mapping'!$D$5:$D$73,MATCH(I$5,'E2 Data Mapping'!$D$5:$D$5,0),FALSE)=0,"",VLOOKUP($D7,'E2 Data Mapping'!$D$5:$D$73,MATCH(I$5,'E2 Data Mapping'!$D$5:$D$5,0),FALSE)),"")
B8: Version | C8: c | D8: ENT-VER-NO | E8: =INDEX('[1]Match Report'!$A$2:$BC$253,MATCH(LEFT(D8,LEN(D8)-1),'[1]Match Report'!$AL$2:$AL$253,0),7) -> #N/A | F8: =IFERROR(IF(VLOOKUP($D8,'E2 Data Mapping'!$D$5:$D$73,MATCH(F$5,'E2 Data Mapping'!$D$5:$D$5,0),FALSE)=0,"",VLOOKUP($D8,'E2 Data Mapping'!$D$5:$D$73,MATCH(F$5,'E2 Data Mapping'!$D$5:$D$5,0),FALSE)),"") | H8: =IFERROR(IF(VLOOKUP($D8,'E2 Data Mapping'!$D$5:$D$73,MATCH(H$5,'E2 Data Mapping'!$D$5:$D$5,0),FALSE)=0,"",VLOOKUP($D8,'E2 Data Mapping'!$D$5:$D$73,MATCH(H$5,'E2 Data Mapping'!$D$5:$D$5,0),FALSE)),"") | I8: =IFERROR(IF(VLOOKUP($D8,'E2 Data Mapping'!$D$5:$D$73,MATCH(I$5,'E2 Data Mapping'!$D$5:$D$5,0),FALSE)=0,"",VLOOKUP($D8,'E2 Data Mapping'!$D$5:$D$73,MATCH(I$5,'E2 Data Mapping'!$D$5:$D$5,0),FALSE)),"")
