Workbook
Name categories: #REF!
Name CATEGORY: [1]Categories!$C:$C
Name cle.code: '[2]DMS.core Code List Elements'!$B$1:$B$757
Name cle.type: '[2]DMS.core Code List Elements'!$A$1:$A$757
Name CODELIST: [1]CodeList!$C:$C
Name CODELIST2: [3]CodeList!$C:$C
Name CODELISTS: #REF!
Name codes: #REF!
Name LASTCODELIST: #REF!
Name OnCODELIST: #REF!
Name wertyhuj: '[4]DMS.core Code Lists'!$B$2:$B$505

Sheet Front Sheet
B4: Document name: | D4: IM and EX Procedure Codes
B5: Instructions: | D5: on the 'Import_Add_Poc_(DE1_11)' and 'Export_Add_Proc_(DE1_11)' sheets - Data entered in the 'Permitted', 'Restricted' and 'Not Permitted' columns should consist only of valid comma-separated Document Types (A,B,C,D,E,F,J,K,Y,Z,Q), without any spaces or any other text or description. Any other information, such as details of the applicable restrictions, or EIDR and SDP applicability / restrictions, should be entered in the Comments column only. This is required to enable the 'read-only' sheets to work correctly. - Each Document Type should appear exactly once for each row, across the above three columns on the Exports sheet (same rule applies on the Imports sheet) - in other words, each Document Type must be clearly classified as one of P (permitted), R (restricted), or N (not permitted) - if mentioned exactly once, the corresponding value (P, R, or N) is displayed in the column for that Declaration Type on the ReadOnly sheet, with the appropriate conditional formatting - if not mentioned, or mentioned more than once, an asterisk is displayed instead, with appropriate conditional formatting - Also note, do not use font colouring or strike-through to retain deleted information. This will mess up the 'read-only' sheets. Instead, use this Front Sheet to track changes.
B6: Explanation: | D6: A couple of intermediate sheets have been protected and hidden.The ReadOnly sheets have been protected. There is NO password, they can be unhidden / unprotected if required to fix any issues (e.g. change the number of lines with the formulae - currently upto row 300) This has been done only to avoid any inadvertent errors.
B7: ReadOnly Sheets: | D7: When 'machine-reading' the ReadOnly sheets, check whether any of the Document Types has an asterisk instead of the P / R / N values. If so, alert a human to investigate.
B9: Version reference | D9: Update | K9: Date
B10: V2.3 | D10: Amended Read-only Sheets conditional formatting to blank out rows where column A is blank | K10: 45128
B11: V2.2 | D11: Amended Front Sheet to enhance the "Instructions" and add the "ReadOnly Sheets" rows | K11: 45119
B12: V2.1 | D12: Amended on SWD request to make it more amenable to automated data extraction - added a 'C21i' column for Imports, and a 'C21e' column for exports - added two intermediate hidden sheets to reduce likelihood of errors on the read-only sheets when changes are made on the editable DE1-11 sheets | K12: 45118
B13: V2.0 | D13: Amended on SWD request to make it more amenable to automated data extraction - added a 'Restricted' column to 'Import_Add_Poc_(DE1_11)' and 'Export_Add_Proc_(DE1_11)' sheets - added a 'C21i' column for Imports, and a 'C21e' column for exports - added two 'read-only' sheets to present the 'Import_Add_Poc_(DE1_11)' and 'Export_Add_Proc_(DE1_11)' data in a more automation-amenable format | K13: 45086
B14: <none> | D14: existing document on HMRC Developer Hub (in directory 'CDS 06 - Tariff Manual' within CDS_Technical_Documentation.zip) | K14: 45071

Sheet Declaration_categories
A1: Procedure codes used in the context of customs declarations Annex B to delegated Regulations (EU 2015/2446)
A2: Declaration Category | B2: Declarations | C2: Union Procedure codes (requested procedure only)
A3: Import
A4: H1 | B4: Declaration for release for free circulation and special procedure - specific use - declaration for end use | C4: 01, 07, 40, 42, 44, 61
A5: H2 | B5: Special procedure - storage - declaration for customs warehousing | C5: 71
A6: H3 | B6: Special procedure - specific use - declaration for temporary admission | C6: 53
A7: H4 | B7: Special procedure - specific use - declaration for inward processing | C7: 51
A8: H5 | B8: Declaration for the introduction of goods in the context of trade with special fiscal territories | C8: 40, 42, 61
A9: I1 | B9: Import Simplified declaration | C9: 01, 07, 40, 42, 44, 51, 53, 61, 71
A10: C21i | B10: Import Customs Clearance Request | C10: 00
A11: C21i EIDR NOP | B11: Import Customs Clearance Request - EIDR Notice of Presentation | C11: 40, 44, 51, 61,71
A13: Export
A14: B1 | B14: Export declaration and re-export declaration | C14: 10, 11, 23, 31
A15: B2 | B15: Special procedure - processing - declaration for outward processing | C15: 21, 22
A16: B4 | B16: Declaration for dispatch of goods in the context of trade with special fiscal territories | C16: 10, 11, 23,31
A17: C1 | B17: Export simplified declaration | C17: 10, 11, 23, 31
A18: C21e | B18: Export Customs Clearance Request | C18: 00
A19: C21e EIDR NOP | B19: Export Customs Clearance Request - EIDR Notice of Presentation | C19: 10,23,31

Sheet Import_Procedure_(DE1-10)
A1: Procedure codes | B1: Declaration category | C1: Dec Type | D1: Add. Dec Type
A2: 4000 | B2: H1, H5, I1 & C21iEIDR | C2: IM, CO | D2: A, B, C, D, E, F, J, K, Y, Z
A3: 4078 | B3: H1, H5, I1 & C21iEIDR | C3: IM, CO | D3: A, B, C, J, Y, Z
A4: 4400 | B4: H1, I1 & C21iEIDR | C4: IM | D4: A, B, C, D, E, F, J, K, Y, Z
A5: 5100 | B5: H4, I1 & C21iEIDR | C5: IM, CO | D5: A, C, D, F, J, K, Y, Z
A6: 5300 | B6: H3, I1 & C21iEIDR | C6: IM, CO | D6: A, C, D, F, J, K, Y, Z
A7: 6110 | B7: H1, H5, I1 & C21iEIDR | C7: IM, CO | D7: A, C, D, F, J, K, Y, Z
A8: 6111 | B8: H1, H5, I1 & C21iEIDR | C8: IM, CO | D8: A, C, D, F, J, K, Y, Z
A9: 6123 | B9: H1, H5, I1 & C21iEIDR | C9: IM, CO | D9: A, C, D, F, J, K, Y, Z
A10: 6131 | B10: H1, H5, I1 & C21iEIDR | C10: IM, CO | D10: A, C, D, F, J, K, Y, Z
A11: 7100 | B11: H2, I1 & C21iEIDR | C11: IM, CO | D11: A, C, D, F, J, K
A12: 7110 | B12: H2, I1 & C21iEIDR | C12: IM, CO | D12: A, C, D, F, J, K
A13: 7123 | B13: H2, I1 & C21iEIDR | C13: IM, CO | D13: A, C, D, F, J, K
A14: Note - For the purposes of this document, the main list of import procedure codes has been reduced to show only those involving EIDR
A16: C21i
A17: 0002 | B17: C21i | C17: IM, CO | D17: J, K
A18: 0003 | B18: C21i | C18: IM, CO | D18: J, K
A19: 0004 | B19: C21i | C19: IM, CO | D19: J, K
A20: 0005 | B20: C21i | C20: IM, CO | D20: J, K
A21: 0006 | B21: C21i | C21: IM | D21: J, K
A22: 0007 | B22: C21i | C22: IM, CO | D22: J, K
A23: 0008 | B23: C21i | C23: IM, CO | D23: J, K
A24: 0009 | B24: C21i | C24: IM | D24: J

Sheet Export_Procedure_(DE1-10)
A1: Procedure codes | B1: Declaration category | C1: Dec Type | D1: Add. Dec Type | E1: Comments
A2: 1040 | B2: B1, B4, C1, C21eEIDR | C2: EX, CO | D2: A, B, C, D, E, F, J, K, Y, Z
A3: 1044 | B3: B1, C1, C21eEIDR | C3: EX | D3: A, C, D, F, J, K, Y, Z
A4: 2300 | B4: B1, B4, C1, C21eEIDR | C4: EX, CO | D4: D, F, K, J, Y, Z
A5: 3151 | B5: B1, B4, C1, C21eEIDR | C5: EX, CO | D5: A, C, D, F, J, K, Y, Z
A6: 3153 | B6: B1, B4, C1, C21eEIDR | C6: EX, CO | D6: A, C, D, F, J, K, Y, Z
A7: 3171 | B7: B1, B4, C1, C21eEIDR | C7: EX, CO | D7: A, C, D, F, J, K, Y, Z
A8: 3178 | B8: B1, B4, C1, C21eEIDR | C8: EX, CO | D8: A, C, D, F, J, K, Y, Z | E8: Export from a Free Zone is now covered by a C21e
A9: Note - For the purposes of this document, the main list of export procedure codes has been reduced to show only those involving EIDR
A11: C21e
A12: 0012 | B12: C21e | C12: EX, CO | D12: J, K | E12: Additional Declaration Type J no longer permitted
A13: 0014 | B13: C21e | C13: EX, CO | D13: J, K | E13: Additional Declaration Type J no longer permitted Declaration type CO no longer permitted
A14: 0015 | B14: C21e | C14: EX, CO | D14: J, K | E14: Additional Declaration Type J no longer permitted
A15: 0016 | B15: C21e | C15: EX, CO | D15: J, K | E15: Additional Declaration Type J no longer permitted
A16: 0017 | B16: C21e | C16: EX, CO | D16: J, K | E16: Additional Declaration Type J no longer permitted
A17: 0018 | B17: C21e | C17: EX, CO | D17: J, K | E17: Additional Declaration Type J no longer permitted
A18: 0019 | B18: C21e | C18: EX | D18: J, K | E18: Additional Declaration Type J no longer permitted

Sheet Import_Add_Proc_(DE1-11)
A1: DE 1/11 | B1: C21i | C1: PERMITTED | D1: RESTRICTED | E1: NOT PERMITTED | F1: Comments
A2: A04 | B2: N | C2: A,C,D,F,J,K,Y,Z | E2: B,E,Q
A3: B02 | B3: N | C3: A,C,D,F,Y | E3: B,E,J,K,Z,Q | F3: EIDR not permitted
A4: B03 | B4: N | C4: A,C,D,F,Y | E4: B,E,J,K,Z,Q | F4: EIDR not permitted
A5: B06 | B5: N | C5: A,C,D,F,Y | E5: B,E,J,K,Z,Q | F5: EIDR not permitted
A6: C01 | B6: N | C6: A,D | E6: B,E,C,F,J,K,Y,Z,Q | F6: EIDR & SDP not permitted
A7: C02 | B7: N | C7: A,D | E7: B,E,C,F,J,K,Y,Z,Q | F7: EIDR & SDP not permitted
A8: C03 | B8: N | C8: A,D | E8: B,E,C,F,J,K,Y,Z,Q | F8: EIDR & SDP not permitted
A9: C04 | B9: N | C9: A,D | D9: C,F,J,K,Y,Z | E9: B,E,Q | F9: EIDR & SDP only with rep status 3
A10: C06 | B10: N | C10: A,D,C,F,J,K,Y,Z | E10: B,E,Q
A11: C07 | B11: N | C11: A,B,D,E,C,F,J,K,Y,Z | E11: Q
A12: C08 | B12: N | C12: A,B,D,E | D12: C,F,J,K,Y,Z | E12: Q | F12: EIDR & SDP only with rep status 3
A13: C09 | B13: N | C13: A,C,D,F,J,K,Y,Z | E13: B,E,Q
A14: C10 | B14: N | C14: A,C,D,F,J,K,Y,Z | E14: B,E,Q
A15: C11 | B15: N | C15: A,C,D,F,J,K,Y,Z | E15: B,E,Q
A16: C12 | B16: N | C16: A,C,D,F,J,K,Y,Z | E16: B,E,Q
A17: C13 | B17: N | C17: A,C,D,F,J,K,Y,Z | E17: B,E,Q
A18: C14 | B18: N | C18: A,C,D,F,J,K,Y,Z | E18: B,E,Q
A19: C15 | B19: N | C19: A,C,D,F,Y | E19: B,E,J,K,Z,Q | F19: EIDR not permitted
A20: C16 | B20: N | C20: A,C,D,F,J,K,Y,Z | E20: B,E,Q
A21: C17 | B21: N | C21: A,C,D,F,J,K,Y,Z | E21: B,E,Q
A22: C18 | B22: N | C22: A,C,D,F,Y, | E22: B,E,J,K,Z,Q | F22: EIDR not permitted
A23: C19 | B23: N | C23: A,D | D23: C,F,J,K,Y,Z | E23: B,E,Q | F23: EIDR & SDP only with rep status 3
A24: C20 | B24: N | C24: A,C,D,F,J,K,Y,Z | E24: B,E,Q
A25: C21 | B25: N | C25: A,C,D,F,J,K,Y,Z | E25: B,E,Q
A26: C22 | B26: N | C26: A,D | D26: C,F,J,K,Y,Z | E26: B,E,Q | F26: EIDR & SDP only with rep status 3
A27: C23 | B27: N | C27: A,C,D,F,J,K,Y,Z | E27: B,E,Q
A28: C24 | B28: N | C28: A,D | D28: C,F,J,K,Y,Z | E28: B,E,Q | F28: EIDR & SDP only with rep status 3
A29: C25 | B29: N | C29: A,C,D,F,J,K,Y,Z | E29: B,E,Q
A30: C26 | B30: N | C30: A,C,D,F,J,K,Y,Z | E30: B,E,Q
A31: C27 | B31: N | C31: A,D | D31: C,F,J,K,Y,Z | E31: B,E,Q | F31: EIDR & SDP only with rep status 3
A32: C28 | B32: N | C32: A,D | D32: C,F,J,K,Y,Z | E32: B,E,Q | F32: EIDR & SDP only with rep status 3
A33: C29 | B33: N | C33: A,D | D33: C,F,J,K,Y,Z | E33: B,E,Q | F33: EIDR & SDP only with rep status 3
A34: C30 | B34: N | C34: A,B,C,D,E,F,J,K,Y,Z | E34: Q
A35: C31 | B35: N | C35: A,C,D,F,J,K,Y,Z | E35: B,E,Q
A36: C32 | B36: N | C36: A,C,D,F,J,K,Y,Z | E36: B,E,Q
A37: C33 | B37: N | C37: A,C,D,F,Y, | E37: B,E,J,K,Z,Q | F37: EIDR not permitted
A38: C34 | B38: N | C38: A,C,D,F,J,K,Y,Z | E38: B,E,Q
A39: C35 | B39: N | C39: A,C,D,F,J,K,Y,Z | E39: B,E,Q
A40: C36 | B40: N | C40: A,C,D,F,J,K,Y,Z | E40: B,E,Q
...

Sheet Import_Add_Proc_(DE1-11) NEW
A1: DE 1/11 | B1: C21i | C1: PERMITTED | D1: RESTRICTED | E1: NOT PERMITTED | F1: Comments
A2: {=IF(ISBLANK(INDIRECT("'Import_Add_Proc_(DE1-11)'!R"&ROW()&"C"&COLUMN(),FALSE)),"",INDIRECT("'Import_Add_Proc_(DE1-11)'!R"&ROW()&"C"&COLUMN(),FALSE))} -> A04 | B2: {=IF(ISBLANK(INDIRECT("'Import_Add_Proc_(DE1-11)'!R"&ROW()&"C"&COLUMN(),FALSE)),"",INDIRECT("'Import_Add_Proc_(DE1-11)'!R"&ROW()&"C"&COLUMN(),FALSE))} -> N | C2: {=IF(ISBLANK(INDIRECT("'Import_Add_Proc_(DE1-11)'!R"&ROW()&"C"&COLUMN(),FALSE)),"",INDIRECT("'Import_Add_Proc_(DE1-11)'!R"&ROW()&"C"&COLUMN(),FALSE))} -> A,C,D,F,J,K,Y,Z | D2: {=IF(ISBLANK(INDIRECT("'Import_Add_Proc_(DE1-11)'!R"&ROW()&"C"&COLUMN(),FALSE)),"",INDIRECT("'Import_Add_Proc_(DE1-11)'!R"&ROW()&"C"&COLUMN(),FALSE))} | E2: {=IF(ISBLANK(INDIRECT("'Import_Add_Proc_(DE1-11)'!R"&ROW()&"C"&COLUMN(),FALSE)),"",INDIRECT("'Import_Add_Proc_(DE1-11)'!R"&ROW()&"C"&COLUMN(),FALSE))} -> B,E,Q | F2: {=IF(ISBLANK(INDIRECT("'Import_Add_Proc_(DE1-11)'!R"&ROW()&"C"&COLUMN(),FALSE)),"",INDIRECT("'Import_Add_Proc_(DE1-11)'!R"&ROW()&"C"&COLUMN(),FALSE))}
A3: {=IF(ISBLANK(INDIRECT("'Import_Add_Proc_(DE1-11)'!R"&ROW()&"C"&COLUMN(),FALSE)),"",INDIRECT("'Import_Add_Proc_(DE1-11)'!R"&ROW()&"C"&COLUMN(),FALSE))} -> B02 | B3: {=IF(ISBLANK(INDIRECT("'Import_Add_Proc_(DE1-11)'!R"&ROW()&"C"&COLUMN(),FALSE)),"",INDIRECT("'Import_Add_Proc_(DE1-11)'!R"&ROW()&"C"&COLUMN(),FALSE))} -> N | C3: {=IF(ISBLANK(INDIRECT("'Import_Add_Proc_(DE1-11)'!R"&ROW()&"C"&COLUMN(),FALSE)),"",INDIRECT("'Import_Add_Proc_(DE1-11)'!R"&ROW()&"C"&COLUMN(),FALSE))} -> A,C,D,F,Y | D3: {=IF(ISBLANK(INDIRECT("'Import_Add_Proc_(DE1-11)'!R"&ROW()&"C"&COLUMN(),FALSE)),"",INDIRECT("'Import_Add_Proc_(DE1-11)'!R"&ROW()&"C"&COLUMN(),FALSE))} | E3: {=IF(ISBLANK(INDIRECT("'Import_Add_Proc_(DE1-11)'!R"&ROW()&"C"&COLUMN(),FALSE)),"",INDIRECT("'Import_Add_Proc_(DE1-11)'!R"&ROW()&"C"&COLUMN(),FALSE))} -> B,E,J,K,Z,Q | F3: {=IF(ISBLANK(INDIRECT("'Import_Add_Proc_(DE1-11)'!R"&ROW()&"C"&COLUMN(),FALSE)),"",INDIRECT("'Import_Add_Proc_(DE1-11)'!R"&ROW()&"C"&COLUMN(),FALSE))} -> EIDR not permitted
A4: {=IF(ISBLANK(INDIRECT("'Import_Add_Proc_(DE1-11)'!R"&ROW()&"C"&COLUMN(),FALSE)),"",INDIRECT("'Import_Add_Proc_(DE1-11)'!R"&ROW()&"C"&COLUMN(),FALSE))} -> B03 | B4: {=IF(ISBLANK(INDIRECT("'Import_Add_Proc_(DE1-11)'!R"&ROW()&"C"&COLUMN(),FALSE)),"",INDIRECT("'Import_Add_Proc_(DE1-11)'!R"&ROW()&"C"&COLUMN(),FALSE))} -> N | C4: {=IF(ISBLANK(INDIRECT("'Import_Add_Proc_(DE1-11)'!R"&ROW()&"C"&COLUMN(),FALSE)),"",INDIRECT("'Import_Add_Proc_(DE1-11)'!R"&ROW()&"C"&COLUMN(),FALSE))} -> A,C,D,F,Y | D4: {=IF(ISBLANK(INDIRECT("'Import_Add_Proc_(DE1-11)'!R"&ROW()&"C"&COLUMN(),FALSE)),"",INDIRECT("'Import_Add_Proc_(DE1-11)'!R"&ROW()&"C"&COLUMN(),FALSE))} | E4: {=IF(ISBLANK(INDIRECT("'Import_Add_Proc_(DE1-11)'!R"&ROW()&"C"&COLUMN(),FALSE)),"",INDIRECT("'Import_Add_Proc_(DE1-11)'!R"&ROW()&"C"&COLUMN(),FALSE))} -> B,E,J,K,Z,Q | F4: {=IF(ISBLANK(INDIRECT("'Import_Add_Proc_(DE1-11)'!R"&ROW()&"C"&COLUMN(),FALSE)),"",INDIRECT("'Import_Add_Proc_(DE1-11)'!R"&ROW()&"C"&COLUMN(),FALSE))} -> EIDR not permitted
A5: {=IF(ISBLANK(INDIRECT("'Import_Add_Proc_(DE1-11)'!R"&ROW()&"C"&COLUMN(),FALSE)),"",INDIRECT("'Import_Add_Proc_(DE1-11)'!R"&ROW()&"C"&COLUMN(),FALSE))} -> B06 | B5: {=IF(ISBLANK(INDIRECT("'Import_Add_Proc_(DE1-11)'!R"&ROW()&"C"&COLUMN(),FALSE)),"",INDIRECT("'Import_Add_Proc_(DE1-11)'!R"&ROW()&"C"&COLUMN(),FALSE))} -> N | C5: {=IF(ISBLANK(INDIRECT("'Import_Add_Proc_(DE1-11)'!R"&ROW()&"C"&COLUMN(),FALSE)),"",INDIRECT("'Import_Add_Proc_(DE1-11)'!R"&ROW()&"C"&COLUMN(),FALSE))} -> A,C,D,F,Y | D5: {=IF(ISBLANK(INDIRECT("'Import_Add_Proc_(DE1-11)'!R"&ROW()&"C"&COLUMN(),FALSE)),"",INDIRECT("'Import_Add_Proc_(DE1-11)'!R"&ROW()&"C"&COLUMN(),FALSE))} | E5: {=IF(ISBLANK(INDIRECT("'Import_Add_Proc_(DE1-11)'!R"&ROW()&"C"&COLUMN(),FALSE)),"",INDIRECT("'Import_Add_Proc_(DE1-11)'!R"&ROW()&"C"&COLUMN(),FALSE))} -> B,E,J,K,Z,Q | F5: {=IF(ISBLANK(INDIRECT("'Import_Add_Proc_(DE1-11)'!R"&ROW()&"C"&COLUMN(),FALSE)),"",INDIRECT("'Import_Add_Proc_(DE1-11)'!R"&ROW()&"C"&COLUMN(),FALSE))} -> EIDR not permitted
A6: {=IF(ISBLANK(INDIRECT("'Import_Add_Proc_(DE1-11)'!R"&ROW()&"C"&COLUMN(),FALSE)),"",INDIRECT("'Import_Add_Proc_(DE1-11)'!R"&ROW()&"C"&COLUMN(),FALSE))} -> C01 | B6: {=IF(ISBLANK(INDIRECT("'Import_Add_Proc_(DE1-11)'!R"&ROW()&"C"&COLUMN(),FALSE)),"",INDIRECT("'Import_Add_Proc_(DE1-11)'!R"&ROW()&"C"&COLUMN(),FALSE))} -> N | C6: {=IF(ISBLANK(INDIRECT("'Import_Add_Proc_(DE1-11)'!R"&ROW()&"C"&COLUMN(),FALSE)),"",INDIRECT("'Import_Add_Proc_(DE1-11)'!R"&ROW()&"C"&COLUMN(),FALSE))} -> A,D | D6: {=IF(ISBLANK(INDIRECT("'Import_Add_Proc_(DE1-11)'!R"&ROW()&"C"&COLUMN(),FALSE)),"",INDIRECT("'Import_Add_Proc_(DE1-11)'!R"&ROW()&"C"&COLUMN(),FALSE))} | E6: {=IF(ISBLANK(INDIRECT("'Import_Add_Proc_(DE1-11)'!R"&ROW()&"C"&COLUMN(),FALSE)),"",INDIRECT("'Import_Add_Proc_(DE1-11)'!R"&ROW()&"C"&COLUMN(),FALSE))} -> B,E,C,F,J,K,Y,Z,Q | F6: {=IF(ISBLANK(INDIRECT("'Import_Add_Proc_(DE1-11)'!R"&ROW()&"C"&COLUMN(),FALSE)),"",INDIRECT("'Import_Add_Proc_(DE1-11)'!R"&ROW()&"C"&COLUMN(),FALSE))} -> EIDR & SDP not permitted
A7: {=IF(ISBLANK(INDIRECT("'Import_Add_Proc_(DE1-11)'!R"&ROW()&"C"&COLUMN(),FALSE)),"",INDIRECT("'Import_Add_Proc_(DE1-11)'!R"&ROW()&"C"&COLUMN(),FALSE))} -> C02 | B7: {=IF(ISBLANK(INDIRECT("'Import_Add_Proc_(DE1-11)'!R"&ROW()&"C"&COLUMN(),FALSE)),"",INDIRECT("'Import_Add_Proc_(DE1-11)'!R"&ROW()&"C"&COLUMN(),FALSE))} -> N | C7: {=IF(ISBLANK(INDIRECT("'Import_Add_Proc_(DE1-11)'!R"&ROW()&"C"&COLUMN(),FALSE)),"",INDIRECT("'Import_Add_Proc_(DE1-11)'!R"&ROW()&"C"&COLUMN(),FALSE))} -> A,D | D7: {=IF(ISBLANK(INDIRECT("'Import_Add_Proc_(DE1-11)'!R"&ROW()&"C"&COLUMN(),FALSE)),"",INDIRECT("'Import_Add_Proc_(DE1-11)'!R"&ROW()&"C"&COLUMN(),FALSE))} | E7: {=IF(ISBLANK(INDIRECT("'Import_Add_Proc_(DE1-11)'!R"&ROW()&"C"&COLUMN(),FALSE)),"",INDIRECT("'Import_Add_Proc_(DE1-11)'!R"&ROW()&"C"&COLUMN(),FALSE))} -> B,E,C,F,J,K,Y,Z,Q | F7: {=IF(ISBLANK(INDIRECT("'Import_Add_Proc_(DE1-11)'!R"&ROW()&"C"&COLUMN(),FALSE)),"",INDIRECT("'Import_Add_Proc_(DE1-11)'!R"&ROW()&"C"&COLUMN(),FALSE))} -> EIDR & SDP not permitted
A8: {=IF(ISBLANK(INDIRECT("'Import_Add_Proc_(DE1-11)'!R"&ROW()&"C"&COLUMN(),FALSE)),"",INDIRECT("'Import_Add_Proc_(DE1-11)'!R"&ROW()&"C"&COLUMN(),FALSE))} -> C03 | B8: {=IF(ISBLANK(INDIRECT("'Import_Add_Proc_(DE1-11)'!R"&ROW()&"C"&COLUMN(),FALSE)),"",INDIRECT("'Import_Add_Proc_(DE1-11)'!R"&ROW()&"C"&COLUMN(),FALSE))} -> N | C8: {=IF(ISBLANK(INDIRECT("'Import_Add_Proc_(DE1-11)'!R"&ROW()&"C"&COLUMN(),FALSE)),"",INDIRECT("'Import_Add_Proc_(DE1-11)'!R"&ROW()&"C"&COLUMN(),FALSE))} -> A,D | D8: {=IF(ISBLANK(INDIRECT("'Import_Add_Proc_(DE1-11)'!R"&ROW()&"C"&COLUMN(),FALSE)),"",INDIRECT("'Import_Add_Proc_(DE1-11)'!R"&ROW()&"C"&COLUMN(),FALSE))} | E8: {=IF(ISBLANK(INDIRECT("'Import_Add_Proc_(DE1-11)'!R"&ROW()&"C"&COLUMN(),FALSE)),"",INDIRECT("'Import_Add_Proc_(DE1-11)'!R"&ROW()&"C"&COLUMN(),FALSE))} -> B,E,C,F,J,K,Y,Z,Q | F8: {=IF(ISBLANK(INDIRECT("'Import_Add_Proc_(DE1-11)'!R"&ROW()&"C"&COLUMN(),FALSE)),"",INDIRECT("'Import_Add_Proc_(DE1-11)'!R"&ROW()&"C"&COLUMN(),FALSE))} -> EIDR & SDP not permitted
A9: {=IF(ISBLANK(INDIRECT("'Import_Add_Proc_(DE1-11)'!R"&ROW()&"C"&COLUMN(),FALSE)),"",INDIRECT("'Import_Add_Proc_(DE1-11)'!R"&ROW()&"C"&COLUMN(),FALSE))} -> C04 | B9: {=IF(ISBLANK(INDIRECT("'Import_Add_Proc_(DE1-11)'!R"&ROW()&"C"&COLUMN(),FALSE)),"",INDIRECT("'Import_Add_Proc_(DE1-11)'!R"&ROW()&"C"&COLUMN(),FALSE))} -> N | C9: {=IF(ISBLANK(INDIRECT("'Import_Add_Proc_(DE1-11)'!R"&ROW()&"C"&COLUMN(),FALSE)),"",INDIRECT("'Import_Add_Proc_(DE1-11)'!R"&ROW()&"C"&COLUMN(),FALSE))} -> A,D | D9: {=IF(ISBLANK(INDIRECT("'Import_Add_Proc_(DE1-11)'!R"&ROW()&"C"&COLUMN(),FALSE)),"",INDIRECT("'Import_Add_Proc_(DE1-11)'!R"&ROW()&"C"&COLUMN(),FALSE))} -> C,F,J,K,Y,Z | E9: {=IF(ISBLANK(INDIRECT("'Import_Add_Proc_(DE1-11)'!R"&ROW()&"C"&COLUMN(),FALSE)),"",INDIRECT("'Import_Add_Proc_(DE1-11)'!R"&ROW()&"C"&COLUMN(),FALSE))} -> B,E,Q | F9: {=IF(ISBLANK(INDIRECT("'Import_Add_Proc_(DE1-11)'!R"&ROW()&"C"&COLUMN(),FALSE)),"",INDIRECT("'Import_Add_Proc_(DE1-11)'!R"&ROW()&"C"&COLUMN(),FALSE))} -> EIDR & SDP only with rep status 3
A10: {=IF(ISBLANK(INDIRECT("'Import_Add_Proc_(DE1-11)'!R"&ROW()&"C"&COLUMN(),FALSE)),"",INDIRECT("'Import_Add_Proc_(DE1-11)'!R"&ROW()&"C"&COLUMN(),FALSE))} -> C06 | B10: {=IF(ISBLANK(INDIRECT("'Import_Add_Proc_(DE1-11)'!R"&ROW()&"C"&COLUMN(),FALSE)),"",INDIRECT("'Import_Add_Proc_(DE1-11)'!R"&ROW()&"C"&COLUMN(),FALSE))} -> N | C10: {=IF(ISBLANK(INDIRECT("'Import_Add_Proc_(DE1-11)'!R"&ROW()&"C"&COLUMN(),FALSE)),"",INDIRECT("'Import_Add_Proc_(DE1-11)'!R"&ROW()&"C"&COLUMN(),FALSE))} -> A,D,C,F,J,K,Y,Z | D10: {=IF(ISBLANK(INDIRECT("'Import_Add_Proc_(DE1-11)'!R"&ROW()&"C"&COLUMN(),FALSE)),"",INDIRECT("'Import_Add_Proc_(DE1-11)'!R"&ROW()&"C"&COLUMN(),FALSE))} | E10: {=IF(ISBLANK(INDIRECT("'Import_Add_Proc_(DE1-11)'!R"&ROW()&"C"&COLUMN(),FALSE)),"",INDIRECT("'Import_Add_Proc_(DE1-11)'!R"&ROW()&"C"&COLUMN(),FALSE))} -> B,E,Q | F10: {=IF(ISBLANK(INDIRECT("'Import_Add_Proc_(DE1-11)'!R"&ROW()&"C"&COLUMN(),FALSE)),"",INDIRECT("'Import_Add_Proc_(DE1-11)'!R"&ROW()&"C"&COLUMN(),FALSE))}
A11: {=IF(ISBLANK(INDIRECT("'Import_Add_Proc_(DE1-11)'!R"&ROW()&"C"&COLUMN(),FALSE)),"",INDIRECT("'Import_Add_Proc_(DE1-11)'!R"&ROW()&"C"&COLUMN(),FALSE))} -> C07 | B11: {=IF(ISBLANK(INDIRECT("'Import_Add_Proc_(DE1-11)'!R"&ROW()&"C"&COLUMN(),FALSE)),"",INDIRECT("'Import_Add_Proc_(DE1-11)'!R"&ROW()&"C"&COLUMN(),FALSE))} -> N | C11: {=IF(ISBLANK(INDIRECT("'Import_Add_Proc_(DE1-11)'!R"&ROW()&"C"&COLUMN(),FALSE)),"",INDIRECT("'Import_Add_Proc_(DE1-11)'!R"&ROW()&"C"&COLUMN(),FALSE))} -> A,B,D,E,C,F,J,K,Y,Z | D11: {=IF(ISBLANK(INDIRECT("'Import_Add_Proc_(DE1-11)'!R"&ROW()&"C"&COLUMN(),FALSE)),"",INDIRECT("'Import_Add_Proc_(DE1-11)'!R"&ROW()&"C"&COLUMN(),FALSE))} | E11: {=IF(ISBLANK(INDIRECT("'Import_Add_Proc_(DE1-11)'!R"&ROW()&"C"&COLUMN(),FALSE)),"",INDIRECT("'Import_Add_Proc_(DE1-11)'!R"&ROW()&"C"&COLUMN(),FALSE))} -> Q | F11: {=IF(ISBLANK(INDIRECT("'Import_Add_Proc_(DE1-11)'!R"&ROW()&"C"&COLUMN(),FALSE)),"",INDIRECT("'Import_Add_Proc_(DE1-11)'!R"&ROW()&"C"&COLUMN(),FALSE))}
A12: {=IF(ISBLANK(INDIRECT("'Import_Add_Proc_(DE1-11)'!R"&ROW()&"C"&COLUMN(),FALSE)),"",INDIRECT("'Import_Add_Proc_(DE1-11)'!R"&ROW()&"C"&COLUMN(),FALSE))} -> C08 | B12: {=IF(ISBLANK(INDIRECT("'Import_Add_Proc_(DE1-11)'!R"&ROW()&"C"&COLUMN(),FALSE)),"",INDIRECT("'Import_Add_Proc_(DE1-11)'!R"&ROW()&"C"&COLUMN(),FALSE))} -> N | C12: {=IF(ISBLANK(INDIRECT("'Import_Add_Proc_(DE1-11)'!R"&ROW()&"C"&COLUMN(),FALSE)),"",INDIRECT("'Import_Add_Proc_(DE1-11)'!R"&ROW()&"C"&COLUMN(),FALSE))} -> A,B,D,E | D12: {=IF(ISBLANK(INDIRECT("'Import_Add_Proc_(DE1-11)'!R"&ROW()&"C"&COLUMN(),FALSE)),"",INDIRECT("'Import_Add_Proc_(DE1-11)'!R"&ROW()&"C"&COLUMN(),FALSE))} -> C,F,J,K,Y,Z | E12: {=IF(ISBLANK(INDIRECT("'Import_Add_Proc_(DE1-11)'!R"&ROW()&"C"&COLUMN(),FALSE)),"",INDIRECT("'Import_Add_Proc_(DE1-11)'!R"&ROW()&"C"&COLUMN(),FALSE))} -> Q | F12: {=IF(ISBLANK(INDIRECT("'Import_Add_Proc_(DE1-11)'!R"&ROW()&"C"&COLUMN(),FALSE)),"",INDIRECT("'Import_Add_Proc_(DE1-11)'!R"&ROW()&"C"&COLUMN(),FALSE))} -> EIDR & SDP only with rep status 3
A13: {=IF(ISBLANK(INDIRECT("'Import_Add_Proc_(DE1-11)'!R"&ROW()&"C"&COLUMN(),FALSE)),"",INDIRECT("'Import_Add_Proc_(DE1-11)'!R"&ROW()&"C"&COLUMN(),FALSE))} -> C09 | B13: {=IF(ISBLANK(INDIRECT("'Import_Add_Proc_(DE1-11)'!R"&ROW()&"C"&COLUMN(),FALSE)),"",INDIRECT("'Import_Add_Proc_(DE1-11)'!R"&ROW()&"C"&COLUMN(),FALSE))} -> N | C13: {=IF(ISBLANK(INDIRECT("'Import_Add_Proc_(DE1-11)'!R"&ROW()&"C"&COLUMN(),FALSE)),"",INDIRECT("'Import_Add_Proc_(DE1-11)'!R"&ROW()&"C"&COLUMN(),FALSE))} -> A,C,D,F,J,K,Y,Z | D13: {=IF(ISBLANK(INDIRECT("'Import_Add_Proc_(DE1-11)'!R"&ROW()&"C"&COLUMN(),FALSE)),"",INDIRECT("'Import_Add_Proc_(DE1-11)'!R"&ROW()&"C"&COLUMN(),FALSE))} | E13: {=IF(ISBLANK(INDIRECT("'Import_Add_Proc_(DE1-11)'!R"&ROW()&"C"&COLUMN(),FALSE)),"",INDIRECT("'Import_Add_Proc_(DE1-11)'!R"&ROW()&"C"&COLUMN(),FALSE))} -> B,E,Q | F13: {=IF(ISBLANK(INDIRECT("'Import_Add_Proc_(DE1-11)'!R"&ROW()&"C"&COLUMN(),FALSE)),"",INDIRECT("'Import_Add_Proc_(DE1-11)'!R"&ROW()&"C"&COLUMN(),FALSE))}
... A300: {=IF(ISBLANK(INDIRECT("'Import_Add_Proc_(DE1-11)'!R"&ROW()&"C"&COLUMN(),FALSE)),"",INDIRECT("'Import_Add_Proc_(DE1-11)'!R"&ROW()&"C"&COLUMN(),FALSE))} | B300: {=IF(ISBLANK(INDIRECT("'Import_Add_Proc_(DE1-11)'!R"&ROW()&"C"&COLUMN(),FALSE)),"",INDIRECT("'Import_Add_Proc_(DE1-11)'!R"&ROW()&"C"&COLUMN(),FALSE))} | C300: {=IF(ISBLANK(INDIRECT("'Import_Add_Proc_(DE1-11)'!R"&ROW()&"C"&COLUMN(),FALSE)),"",INDIRECT("'Import_Add_Proc_(DE1-11)'!R"&ROW()&"C"&COLUMN(),FALSE))} | D300: {=IF(ISBLANK(INDIRECT("'Import_Add_Proc_(DE1-11)'!R"&ROW()&"C"&COLUMN(),FALSE)),"",INDIRECT("'Import_Add_Proc_(DE1-11)'!R"&ROW()&"C"&COLUMN(),FALSE))} | E300: {=IF(ISBLANK(INDIRECT("'Import_Add_Proc_(DE1-11)'!R"&ROW()&"C"&COLUMN(),FALSE)),"",INDIRECT("'Import_Add_Proc_(DE1-11)'!R"&ROW()&"C"&COLUMN(),FALSE))} | F300: {=IF(ISBLANK(INDIRECT("'Import_Add_Proc_(DE1-11)'!R"&ROW()&"C"&COLUMN(),FALSE)),"",INDIRECT("'Import_Add_Proc_(DE1-11)'!R"&ROW()&"C"&COLUMN(),FALSE))}

Sheet Import_DE1-11_ReadOnly
A1: DE 1/11 | B1: C21i | C1: A | D1: B | E1: C | F1: D | G1: E | H1: F | I1: J | J1: K | K1: Y | L1: Z | M1: Q | N1: Comments | O1: A | P1: B | Q1: C | R1: D | S1: E | T1: F | U1: J | V1: K | W1: Y | X1: Z | Y1: Q | Z1: =O1 -> A | AA1: =P1 -> B | AB1: =Q1 -> C | AC1: =R1 -> D | AD1: =S1 -> E | AE1: =T1 -> F | AF1: =U1 -> J | AG1: =V1 -> K | ... BF1: =AU1 -> Q
A2: ='Import_Add_Proc_(DE1-11) NEW'!A2 -> A04 | B2: ='Import_Add_Proc_(DE1-11) NEW'!B2 -> N | C2: =IF(AV2<>1,"*",IF(O2,"P",IF(Z2,"R","N"))) -> P | D2: =IF(AW2<>1,"*",IF(P2,"P",IF(AA2,"R","N"))) -> N | E2: =IF(AX2<>1,"*",IF(Q2,"P",IF(AB2,"R","N"))) -> P | F2: =IF(AY2<>1,"*",IF(R2,"P",IF(AC2,"R","N"))) -> P | G2: =IF(AZ2<>1,"*",IF(S2,"P",IF(AD2,"R","N"))) -> N | H2: =IF(BA2<>1,"*",IF(T2,"P",IF(AE2,"R","N"))) -> P | I2: =IF(BB2<>1,"*",IF(U2,"P",IF(AF2,"R","N"))) -> P | J2: =IF(BC2<>1,"*",IF(V2,"P",IF(AG2,"R","N"))) -> P | ... M2: =IF(BF2<>1,"*",IF(Y2,"P",IF(AJ2,"R","N"))) -> N | N2: =IF(ISBLANK('Import_Add_Proc_(DE1-11) NEW'!F2),"",'Import_Add_Proc_(DE1-11) NEW'!F2) | O2: =IF(ISERROR(FIND(O$1,'Import_Add_Proc_(DE1-11) NEW'!$C2)),0,1) -> 1 | P2: =IF(ISERROR(FIND(P$1,'Import_Add_Proc_(DE1-11) NEW'!$C2)),0,1) -> 0 | Q2: =IF(ISERROR(FIND(Q$1,'Import_Add_Proc_(DE1-11) NEW'!$C2)),0,1) -> 1 | R2: =IF(ISERROR(FIND(R$1,'Import_Add_Proc_(DE1-11) NEW'!$C2)),0,1) -> 1 | S2: =IF(ISERROR(FIND(S$1,'Import_Add_Proc_(DE1-11) NEW'!$C2)),0,1) -> 0 | T2: =IF(ISERROR(FIND(T$1,'Import_Add_Proc_(DE1-11) NEW'!$C2)),0,1) -> 1 | U2: =IF(ISERROR(FIND(U$1,'Import_Add_Proc_(DE1-11) NEW'!$C2)),0,1) -> 1 | V2: =IF(ISERROR(FIND(V$1,'Import_Add_Proc_(DE1-11) NEW'!$C2)),0,1) -> 1 | ... Y2: =IF(ISERROR(FIND(Y$1,'Import_Add_Proc_(DE1-11) NEW'!$C2)),0,1) -> 0 | Z2: =IF(ISERROR(FIND(Z$1,'Import_Add_Proc_(DE1-11) NEW'!$D2)),0,1) -> 0 | AA2: =IF(ISERROR(FIND(AA$1,'Import_Add_Proc_(DE1-11) NEW'!$D2)),0,1) -> 0 | AB2: =IF(ISERROR(FIND(AB$1,'Import_Add_Proc_(DE1-11) NEW'!$D2)),0,1) -> 0 | AC2: =IF(ISERROR(FIND(AC$1,'Import_Add_Proc_(DE1-11) NEW'!$D2)),0,1) -> 0 | AD2: =IF(ISERROR(FIND(AD$1,'Import_Add_Proc_(DE1-11) NEW'!$D2)),0,1) -> 0 | AE2: =IF(ISERROR(FIND(AE$1,'Import_Add_Proc_(DE1-11) NEW'!$D2)),0,1) -> 0 | AF2: =IF(ISERROR(FIND(AF$1,'Import_Add_Proc_(DE1-11) NEW'!$D2)),0,1) -> 0 | AG2: =IF(ISERROR(FIND(AG$1,'Import_Add_Proc_(DE1-11) NEW'!$D2)),0,1) -> 0 | ... AJ2: =IF(ISERROR(FIND(AJ$1,'Import_Add_Proc_(DE1-11) NEW'!$D2)),0,1) -> 0 | AK2: =IF(ISERROR(FIND(AK$1,'Import_Add_Proc_(DE1-11) NEW'!$E2)),0,1) -> 0 | AL2: =IF(ISERROR(FIND(AL$1,'Import_Add_Proc_(DE1-11) NEW'!$E2)),0,1) -> 1 | AM2: =IF(ISERROR(FIND(AM$1,'Import_Add_Proc_(DE1-11) NEW'!$E2)),0,1) -> 0 | AN2: =IF(ISERROR(FIND(AN$1,'Import_Add_Proc_(DE1-11) NEW'!$E2)),0,1) -> 0 | AO2: =IF(ISERROR(FIND(AO$1,'Import_Add_Proc_(DE1-11) NEW'!$E2)),0,1) -> 1 | AP2: =IF(ISERROR(FIND(AP$1,'Import_Add_Proc_(DE1-11) NEW'!$E2)),0,1) -> 0 | AQ2: =IF(ISERROR(FIND(AQ$1,'Import_Add_Proc_(DE1-11) NEW'!$E2)),0,1) -> 0 | AR2: =IF(ISERROR(FIND(AR$1,'Import_Add_Proc_(DE1-11) NEW'!$E2)),0,1) -> 0 | ... AU2: =IF(ISERROR(FIND(AU$1,'Import_Add_Proc_(DE1-11) NEW'!$E2)),0,1) -> 1 | AV2: =O2+Z2+AK2 -> 1 | AW2: =P2+AA2+AL2 -> 1 | AX2: =Q2+AB2+AM2 -> 1 | AY2: =R2+AC2+AN2 -> 1 | AZ2: =S2+AD2+AO2 -> 1 | BA2: =T2+AE2+AP2 -> 1 | BB2: =U2+AF2+AQ2 -> 1 | BC2: =V2+AG2+AR2 -> 1 | ... BF2: =Y2+AJ2+AU2 -> 1
A3: ='Import_Add_Proc_(DE1-11) NEW'!A3 -> B02 | B3: ='Import_Add_Proc_(DE1-11) NEW'!B3 -> N | C3: =IF(AV3<>1,"*",IF(O3,"P",IF(Z3,"R","N"))) -> P | D3: =IF(AW3<>1,"*",IF(P3,"P",IF(AA3,"R","N"))) -> N | E3: =IF(AX3<>1,"*",IF(Q3,"P",IF(AB3,"R","N"))) -> P | F3: =IF(AY3<>1,"*",IF(R3,"P",IF(AC3,"R","N"))) -> P | G3: =IF(AZ3<>1,"*",IF(S3,"P",IF(AD3,"R","N"))) -> N | H3: =IF(BA3<>1,"*",IF(T3,"P",IF(AE3,"R","N"))) -> P | I3: =IF(BB3<>1,"*",IF(U3,"P",IF(AF3,"R","N"))) -> N | J3: =IF(BC3<>1,"*",IF(V3,"P",IF(AG3,"R","N"))) -> N | ... M3: =IF(BF3<>1,"*",IF(Y3,"P",IF(AJ3,"R","N"))) -> N | N3: =IF(ISBLANK('Import_Add_Proc_(DE1-11) NEW'!F3),"",'Import_Add_Proc_(DE1-11) NEW'!F3) -> EIDR not permitted | O3: =IF(ISERROR(FIND(O$1,'Import_Add_Proc_(DE1-11) NEW'!$C3)),0,1) -> 1 | P3: =IF(ISERROR(FIND(P$1,'Import_Add_Proc_(DE1-11) NEW'!$C3)),0,1) -> 0 | Q3: =IF(ISERROR(FIND(Q$1,'Import_Add_Proc_(DE1-11) NEW'!$C3)),0,1) -> 1 | R3: =IF(ISERROR(FIND(R$1,'Import_Add_Proc_(DE1-11) NEW'!$C3)),0,1) -> 1 | S3: =IF(ISERROR(FIND(S$1,'Import_Add_Proc_(DE1-11) NEW'!$C3)),0,1) -> 0 | T3: =IF(ISERROR(FIND(T$1,'Import_Add_Proc_(DE1-11) NEW'!$C3)),0,1) -> 1 | U3: =IF(ISERROR(FIND(U$1,'Import_Add_Proc_(DE1-11) NEW'!$C3)),0,1) -> 0 | V3: =IF(ISERROR(FIND(V$1,'Import_Add_Proc_(DE1-11) NEW'!$C3)),0,1) -> 0 | ... Y3: =IF(ISERROR(FIND(Y$1,'Import_Add_Proc_(DE1-11) NEW'!$C3)),0,1) -> 0 | Z3: =IF(ISERROR(FIND(Z$1,'Import_Add_Proc_(DE1-11) NEW'!$D3)),0,1) -> 0 | AA3: =IF(ISERROR(FIND(AA$1,'Import_Add_Proc_(DE1-11) NEW'!$D3)),0,1) -> 0 | AB3: =IF(ISERROR(FIND(AB$1,'Import_Add_Proc_(DE1-11) NEW'!$D3)),0,1) -> 0 | AC3: =IF(ISERROR(FIND(AC$1,'Import_Add_Proc_(DE1-11) NEW'!$D3)),0,1) -> 0 | AD3: =IF(ISERROR(FIND(AD$1,'Import_Add_Proc_(DE1-11) NEW'!$D3)),0,1) -> 0 | AE3: =IF(ISERROR(FIND(AE$1,'Import_Add_Proc_(DE1-11) NEW'!$D3)),0,1) -> 0 | AF3: =IF(ISERROR(FIND(AF$1,'Import_Add_Proc_(DE1-11) NEW'!$D3)),0,1) -> 0 | AG3: =IF(ISERROR(FIND(AG$1,'Import_Add_Proc_(DE1-11) NEW'!$D3)),0,1) -> 0 | ... AJ3: =IF(ISERROR(FIND(AJ$1,'Import_Add_Proc_(DE1-11) NEW'!$D3)),0,1) -> 0 | AK3: =IF(ISERROR(FIND(AK$1,'Import_Add_Proc_(DE1-11) NEW'!$E3)),0,1) -> 0 | AL3: =IF(ISERROR(FIND(AL$1,'Import_Add_Proc_(DE1-11) NEW'!$E3)),0,1) -> 1 | AM3: =IF(ISERROR(FIND(AM$1,'Import_Add_Proc_(DE1-11) NEW'!$E3)),0,1) -> 0 | AN3: =IF(ISERROR(FIND(AN$1,'Import_Add_Proc_(DE1-11) NEW'!$E3)),0,1) -> 0 | AO3: =IF(ISERROR(FIND(AO$1,'Import_Add_Proc_(DE1-11) NEW'!$E3)),0,1) -> 1 | AP3: =IF(ISERROR(FIND(AP$1,'Import_Add_Proc_(DE1-11) NEW'!$E3)),0,1) -> 0 | AQ3: =IF(ISERROR(FIND(AQ$1,'Import_Add_Proc_(DE1-11) NEW'!$E3)),0,1) -> 1 | AR3: =IF(ISERROR(FIND(AR$1,'Import_Add_Proc_(DE1-11) NEW'!$E3)),0,1) -> 1 | ... AU3: =IF(ISERROR(FIND(AU$1,'Import_Add_Proc_(DE1-11) NEW'!$E3)),0,1) -> 1 | AV3: =O3+Z3+AK3 -> 1 | AW3: =P3+AA3+AL3 -> 1 | AX3: =Q3+AB3+AM3 -> 1 | AY3: =R3+AC3+AN3 -> 1 | AZ3: =S3+AD3+AO3 -> 1 | BA3: =T3+AE3+AP3 -> 1 | BB3: =U3+AF3+AQ3 -> 1 | BC3: =V3+AG3+AR3 -> 1 | ... BF3: =Y3+AJ3+AU3 -> 1
A4: ='Import_Add_Proc_(DE1-11) NEW'!A4 -> B03 | B4: ='Import_Add_Proc_(DE1-11) NEW'!B4 -> N | C4: =IF(AV4<>1,"*",IF(O4,"P",IF(Z4,"R","N"))) -> P | D4: =IF(AW4<>1,"*",IF(P4,"P",IF(AA4,"R","N"))) -> N | E4: =IF(AX4<>1,"*",IF(Q4,"P",IF(AB4,"R","N"))) -> P | F4: =IF(AY4<>1,"*",IF(R4,"P",IF(AC4,"R","N"))) -> P | G4: =IF(AZ4<>1,"*",IF(S4,"P",IF(AD4,"R","N"))) -> N | H4: =IF(BA4<>1,"*",IF(T4,"P",IF(AE4,"R","N"))) -> P | I4: =IF(BB4<>1,"*",IF(U4,"P",IF(AF4,"R","N"))) -> N | J4: =IF(BC4<>1,"*",IF(V4,"P",IF(AG4,"R","N"))) -> N | ... M4: =IF(BF4<>1,"*",IF(Y4,"P",IF(AJ4,"R","N"))) -> N | N4: =IF(ISBLANK('Import_Add_Proc_(DE1-11) NEW'!F4),"",'Import_Add_Proc_(DE1-11) NEW'!F4) -> EIDR not permitted | O4: =IF(ISERROR(FIND(O$1,'Import_Add_Proc_(DE1-11) NEW'!$C4)),0,1) -> 1 | P4: =IF(ISERROR(FIND(P$1,'Import_Add_Proc_(DE1-11) NEW'!$C4)),0,1) -> 0 | Q4: =IF(ISERROR(FIND(Q$1,'Import_Add_Proc_(DE1-11) NEW'!$C4)),0,1) -> 1 | R4: =IF(ISERROR(FIND(R$1,'Import_Add_Proc_(DE1-11) NEW'!$C4)),0,1) -> 1 | S4: =IF(ISERROR(FIND(S$1,'Import_Add_Proc_(DE1-11) NEW'!$C4)),0,1) -> 0 | T4: =IF(ISERROR(FIND(T$1,'Import_Add_Proc_(DE1-11) NEW'!$C4)),0,1) -> 1 | U4: =IF(ISERROR(FIND(U$1,'Import_Add_Proc_(DE1-11) NEW'!$C4)),0,1) -> 0 | V4: =IF(ISERROR(FIND(V$1,'Import_Add_Proc_(DE1-11) NEW'!$C4)),0,1) -> 0 | ... Y4: =IF(ISERROR(FIND(Y$1,'Import_Add_Proc_(DE1-11) NEW'!$C4)),0,1) -> 0 | Z4: =IF(ISERROR(FIND(Z$1,'Import_Add_Proc_(DE1-11) NEW'!$D4)),0,1) -> 0 | AA4: =IF(ISERROR(FIND(AA$1,'Import_Add_Proc_(DE1-11) NEW'!$D4)),0,1) -> 0 | AB4: =IF(ISERROR(FIND(AB$1,'Import_Add_Proc_(DE1-11) NEW'!$D4)),0,1) -> 0 | AC4: =IF(ISERROR(FIND(AC$1,'Import_Add_Proc_(DE1-11) NEW'!$D4)),0,1) -> 0 | AD4: =IF(ISERROR(FIND(AD$1,'Import_Add_Proc_(DE1-11) NEW'!$D4)),0,1) -> 0 | AE4: =IF(ISERROR(FIND(AE$1,'Import_Add_Proc_(DE1-11) NEW'!$D4)),0,1) -> 0 | AF4: =IF(ISERROR(FIND(AF$1,'Import_Add_Proc_(DE1-11) NEW'!$D4)),0,1) -> 0 | AG4: =IF(ISERROR(FIND(AG$1,'Import_Add_Proc_(DE1-11) NEW'!$D4)),0,1) -> 0 | ... AJ4: =IF(ISERROR(FIND(AJ$1,'Import_Add_Proc_(DE1-11) NEW'!$D4)),0,1) -> 0 | AK4: =IF(ISERROR(FIND(AK$1,'Import_Add_Proc_(DE1-11) NEW'!$E4)),0,1) -> 0 | AL4: =IF(ISERROR(FIND(AL$1,'Import_Add_Proc_(DE1-11) NEW'!$E4)),0,1) -> 1 | AM4: =IF(ISERROR(FIND(AM$1,'Import_Add_Proc_(DE1-11) NEW'!$E4)),0,1) -> 0 | AN4: =IF(ISERROR(FIND(AN$1,'Import_Add_Proc_(DE1-11) NEW'!$E4)),0,1) -> 0 | AO4: =IF(ISERROR(FIND(AO$1,'Import_Add_Proc_(DE1-11) NEW'!$E4)),0,1) -> 1 | AP4: =IF(ISERROR(FIND(AP$1,'Import_Add_Proc_(DE1-11) NEW'!$E4)),0,1) -> 0 | AQ4: =IF(ISERROR(FIND(AQ$1,'Import_Add_Proc_(DE1-11) NEW'!$E4)),0,1) -> 1 | AR4: =IF(ISERROR(FIND(AR$1,'Import_Add_Proc_(DE1-11) NEW'!$E4)),0,1) -> 1 | ... AU4: =IF(ISERROR(FIND(AU$1,'Import_Add_Proc_(DE1-11) NEW'!$E4)),0,1) -> 1 | AV4: =O4+Z4+AK4 -> 1 | AW4: =P4+AA4+AL4 -> 1 | AX4: =Q4+AB4+AM4 -> 1 | AY4: =R4+AC4+AN4 -> 1 | AZ4: =S4+AD4+AO4 -> 1 | BA4: =T4+AE4+AP4 -> 1 | BB4: =U4+AF4+AQ4 -> 1 | BC4: =V4+AG4+AR4 -> 1 | ... BF4: =Y4+AJ4+AU4 -> 1
A5: ='Import_Add_Proc_(DE1-11) NEW'!A5 -> B06 | B5: ='Import_Add_Proc_(DE1-11) NEW'!B5 -> N | C5: =IF(AV5<>1,"*",IF(O5,"P",IF(Z5,"R","N"))) -> P | D5: =IF(AW5<>1,"*",IF(P5,"P",IF(AA5,"R","N"))) -> N | E5: =IF(AX5<>1,"*",IF(Q5,"P",IF(AB5,"R","N"))) -> P | F5: =IF(AY5<>1,"*",IF(R5,"P",IF(AC5,"R","N"))) -> P | G5: =IF(AZ5<>1,"*",IF(S5,"P",IF(AD5,"R","N"))) -> N | H5: =IF(BA5<>1,"*",IF(T5,"P",IF(AE5,"R","N"))) -> P | I5: =IF(BB5<>1,"*",IF(U5,"P",IF(AF5,"R","N"))) -> N | J5: =IF(BC5<>1,"*",IF(V5,"P",IF(AG5,"R","N"))) -> N | ... M5: =IF(BF5<>1,"*",IF(Y5,"P",IF(AJ5,"R","N"))) -> N | N5: =IF(ISBLANK('Import_Add_Proc_(DE1-11) NEW'!F5),"",'Import_Add_Proc_(DE1-11) NEW'!F5) -> EIDR not permitted | O5: =IF(ISERROR(FIND(O$1,'Import_Add_Proc_(DE1-11) NEW'!$C5)),0,1) -> 1 | P5: =IF(ISERROR(FIND(P$1,'Import_Add_Proc_(DE1-11) NEW'!$C5)),0,1) -> 0 | Q5: =IF(ISERROR(FIND(Q$1,'Import_Add_Proc_(DE1-11) NEW'!$C5)),0,1) -> 1 | R5: =IF(ISERROR(FIND(R$1,'Import_Add_Proc_(DE1-11) NEW'!$C5)),0,1) -> 1 | S5: =IF(ISERROR(FIND(S$1,'Import_Add_Proc_(DE1-11) NEW'!$C5)),0,1) -> 0 | T5: =IF(ISERROR(FIND(T$1,'Import_Add_Proc_(DE1-11) NEW'!$C5)),0,1) -> 1 | U5: =IF(ISERROR(FIND(U$1,'Import_Add_Proc_(DE1-11) NEW'!$C5)),0,1) -> 0 | V5: =IF(ISERROR(FIND(V$1,'Import_Add_Proc_(DE1-11) NEW'!$C5)),0,1) -> 0 | ... Y5: =IF(ISERROR(FIND(Y$1,'Import_Add_Proc_(DE1-11) NEW'!$C5)),0,1) -> 0 | Z5: =IF(ISERROR(FIND(Z$1,'Import_Add_Proc_(DE1-11) NEW'!$D5)),0,1) -> 0 | AA5: =IF(ISERROR(FIND(AA$1,'Import_Add_Proc_(DE1-11) NEW'!$D5)),0,1) -> 0 | AB5: =IF(ISERROR(FIND(AB$1,'Import_Add_Proc_(DE1-11) NEW'!$D5)),0,1) -> 0 | AC5: =IF(ISERROR(FIND(AC$1,'Import_Add_Proc_(DE1-11) NEW'!$D5)),0,1) -> 0 | AD5: =IF(ISERROR(FIND(AD$1,'Import_Add_Proc_(DE1-11) NEW'!$D5)),0,1) -> 0 | AE5: =IF(ISERROR(FIND(AE$1,'Import_Add_Proc_(DE1-11) NEW'!$D5)),0,1) -> 0 | AF5: =IF(ISERROR(FIND(AF$1,'Import_Add_Proc_(DE1-11) NEW'!$D5)),0,1) -> 0 | AG5: =IF(ISERROR(FIND(AG$1,'Import_Add_Proc_(DE1-11) NEW'!$D5)),0,1) -> 0 | ... AJ5: =IF(ISERROR(FIND(AJ$1,'Import_Add_Proc_(DE1-11) NEW'!$D5)),0,1) -> 0 | AK5: =IF(ISERROR(FIND(AK$1,'Import_Add_Proc_(DE1-11) NEW'!$E5)),0,1) -> 0 | AL5: =IF(ISERROR(FIND(AL$1,'Import_Add_Proc_(DE1-11) NEW'!$E5)),0,1) -> 1 | AM5: =IF(ISERROR(FIND(AM$1,'Import_Add_Proc_(DE1-11) NEW'!$E5)),0,1) -> 0 | AN5: =IF(ISERROR(FIND(AN$1,'Import_Add_Proc_(DE1-11) NEW'!$E5)),0,1) -> 0 | AO5: =IF(ISERROR(FIND(AO$1,'Import_Add_Proc_(DE1-11) NEW'!$E5)),0,1) -> 1 | AP5: =IF(ISERROR(FIND(AP$1,'Import_Add_Proc_(DE1-11) NEW'!$E5)),0,1) -> 0 | AQ5: =IF(ISERROR(FIND(AQ$1,'Import_Add_Proc_(DE1-11) NEW'!$E5)),0,1) -> 1 | AR5: =IF(ISERROR(FIND(AR$1,'Import_Add_Proc_(DE1-11) NEW'!$E5)),0,1) -> 1 | ... AU5: =IF(ISERROR(FIND(AU$1,'Import_Add_Proc_(DE1-11) NEW'!$E5)),0,1) -> 1 | AV5: =O5+Z5+AK5 -> 1 | AW5: =P5+AA5+AL5 -> 1 | AX5: =Q5+AB5+AM5 -> 1 | AY5: =R5+AC5+AN5 -> 1 | AZ5: =S5+AD5+AO5 -> 1 | BA5: =T5+AE5+AP5 -> 1 | BB5: =U5+AF5+AQ5 -> 1 | BC5: =V5+AG5+AR5 -> 1 | ... BF5: =Y5+AJ5+AU5 -> 1
A6: ='Import_Add_Proc_(DE1-11) NEW'!A6 -> C01 | B6: ='Import_Add_Proc_(DE1-11) NEW'!B6 -> N | C6: =IF(AV6<>1,"*",IF(O6,"P",IF(Z6,"R","N"))) -> P | D6: =IF(AW6<>1,"*",IF(P6,"P",IF(AA6,"R","N"))) -> N | E6: =IF(AX6<>1,"*",IF(Q6,"P",IF(AB6,"R","N"))) -> N | F6: =IF(AY6<>1,"*",IF(R6,"P",IF(AC6,"R","N"))) -> P | G6: =IF(AZ6<>1,"*",IF(S6,"P",IF(AD6,"R","N"))) -> N | H6: =IF(BA6<>1,"*",IF(T6,"P",IF(AE6,"R","N"))) -> N | I6: =IF(BB6<>1,"*",IF(U6,"P",IF(AF6,"R","N"))) -> N | J6: =IF(BC6<>1,"*",IF(V6,"P",IF(AG6,"R","N"))) -> N | ... M6: =IF(BF6<>1,"*",IF(Y6,"P",IF(AJ6,"R","N"))) -> N | N6: =IF(ISBLANK('Import_Add_Proc_(DE1-11) NEW'!F6),"",'Import_Add_Proc_(DE1-11) NEW'!F6) -> EIDR & SDP not permitted | O6: =IF(ISERROR(FIND(O$1,'Import_Add_Proc_(DE1-11) NEW'!$C6)),0,1) -> 1 | P6: =IF(ISERROR(FIND(P$1,'Import_Add_Proc_(DE1-11) NEW'!$C6)),0,1) -> 0 | Q6: =IF(ISERROR(FIND(Q$1,'Import_Add_Proc_(DE1-11) NEW'!$C6)),0,1) -> 0 | R6: =IF(ISERROR(FIND(R$1,'Import_Add_Proc_(DE1-11) NEW'!$C6)),0,1) -> 1 | S6: =IF(ISERROR(FIND(S$1,'Import_Add_Proc_(DE1-11) NEW'!$C6)),0,1) -> 0 | T6: =IF(ISERROR(FIND(T$1,'Import_Add_Proc_(DE1-11) NEW'!$C6)),0,1) -> 0 | U6: =IF(ISERROR(FIND(U$1,'Import_Add_Proc_(DE1-11) NEW'!$C6)),0,1) -> 0 | V6: =IF(ISERROR(FIND(V$1,'Import_Add_Proc_(DE1-11) NEW'!$C6)),0,1) -> 0 | ... Y6: =IF(ISERROR(FIND(Y$1,'Import_Add_Proc_(DE1-11) NEW'!$C6)),0,1) -> 0 | Z6: =IF(ISERROR(FIND(Z$1,'Import_Add_Proc_(DE1-11) NEW'!$D6)),0,1) -> 0 | AA6: =IF(ISERROR(FIND(AA$1,'Import_Add_Proc_(DE1-11) NEW'!$D6)),0,1) -> 0 | AB6: =IF(ISERROR(FIND(AB$1,'Import_Add_Proc_(DE1-11) NEW'!$D6)),0,1) -> 0 | AC6: =IF(ISERROR(FIND(AC$1,'Import_Add_Proc_(DE1-11) NEW'!$D6)),0,1) -> 0 | AD6: =IF(ISERROR(FIND(AD$1,'Import_Add_Proc_(DE1-11) NEW'!$D6)),0,1) -> 0 | AE6: =IF(ISERROR(FIND(AE$1,'Import_Add_Proc_(DE1-11) NEW'!$D6)),0,1) -> 0 | AF6: =IF(ISERROR(FIND(AF$1,'Import_Add_Proc_(DE1-11) NEW'!$D6)),0,1) -> 0 | AG6: =IF(ISERROR(FIND(AG$1,'Import_Add_Proc_(DE1-11) NEW'!$D6)),0,1) -> 0 | ... AJ6: =IF(ISERROR(FIND(AJ$1,'Import_Add_Proc_(DE1-11) NEW'!$D6)),0,1) -> 0 | AK6: =IF(ISERROR(FIND(AK$1,'Import_Add_Proc_(DE1-11) NEW'!$E6)),0,1) -> 0 | AL6: =IF(ISERROR(FIND(AL$1,'Import_Add_Proc_(DE1-11) NEW'!$E6)),0,1) -> 1 | AM6: =IF(ISERROR(FIND(AM$1,'Import_Add_Proc_(DE1-11) NEW'!$E6)),0,1) -> 1 | AN6: =IF(ISERROR(FIND(AN$1,'Import_Add_Proc_(DE1-11) NEW'!$E6)),0,1) -> 0 | AO6: =IF(ISERROR(FIND(AO$1,'Import_Add_Proc_(DE1-11) NEW'!$E6)),0,1) -> 1 | AP6: =IF(ISERROR(FIND(AP$1,'Import_Add_Proc_(DE1-11) NEW'!$E6)),0,1) -> 1 | AQ6: =IF(ISERROR(FIND(AQ$1,'Import_Add_Proc_(DE1-11) NEW'!$E6)),0,1) -> 1 | AR6: =IF(ISERROR(FIND(AR$1,'Import_Add_Proc_(DE1-11) NEW'!$E6)),0,1) -> 1 | ... AU6: =IF(ISERROR(FIND(AU$1,'Import_Add_Proc_(DE1-11) NEW'!$E6)),0,1) -> 1 | AV6: =O6+Z6+AK6 -> 1 | AW6: =P6+AA6+AL6 -> 1 | AX6: =Q6+AB6+AM6 -> 1 | AY6: =R6+AC6+AN6 -> 1 | AZ6: =S6+AD6+AO6 -> 1 | BA6: =T6+AE6+AP6 -> 1 | BB6: =U6+AF6+AQ6 -> 1 | BC6: =V6+AG6+AR6 -> 1 | ... BF6: =Y6+AJ6+AU6 -> 1
A7: ='Import_Add_Proc_(DE1-11) NEW'!A7 -> C02 | B7: ='Import_Add_Proc_(DE1-11) NEW'!B7 -> N | C7: =IF(AV7<>1,"*",IF(O7,"P",IF(Z7,"R","N"))) -> P | D7: =IF(AW7<>1,"*",IF(P7,"P",IF(AA7,"R","N"))) -> N | E7: =IF(AX7<>1,"*",IF(Q7,"P",IF(AB7,"R","N"))) -> N | F7: =IF(AY7<>1,"*",IF(R7,"P",IF(AC7,"R","N"))) -> P | G7: =IF(AZ7<>1,"*",IF(S7,"P",IF(AD7,"R","N"))) -> N | H7: =IF(BA7<>1,"*",IF(T7,"P",IF(AE7,"R","N"))) -> N | I7: =IF(BB7<>1,"*",IF(U7,"P",IF(AF7,"R","N"))) -> N | J7: =IF(BC7<>1,"*",IF(V7,"P",IF(AG7,"R","N"))) -> N | ... M7: =IF(BF7<>1,"*",IF(Y7,"P",IF(AJ7,"R","N"))) -> N | N7: =IF(ISBLANK('Import_Add_Proc_(DE1-11) NEW'!F7),"",'Import_Add_Proc_(DE1-11) NEW'!F7) -> EIDR & SDP not permitted | O7: =IF(ISERROR(FIND(O$1,'Import_Add_Proc_(DE1-11) NEW'!$C7)),0,1) -> 1 | P7: =IF(ISERROR(FIND(P$1,'Import_Add_Proc_(DE1-11) NEW'!$C7)),0,1) -> 0 | Q7: =IF(ISERROR(FIND(Q$1,'Import_Add_Proc_(DE1-11) NEW'!$C7)),0,1) -> 0 | R7: =IF(ISERROR(FIND(R$1,'Import_Add_Proc_(DE1-11) NEW'!$C7)),0,1) -> 1 | S7: =IF(ISERROR(FIND(S$1,'Import_Add_Proc_(DE1-11) NEW'!$C7)),0,1) -> 0 | T7: =IF(ISERROR(FIND(T$1,'Import_Add_Proc_(DE1-11) NEW'!$C7)),0,1) -> 0 | U7: =IF(ISERROR(FIND(U$1,'Import_Add_Proc_(DE1-11) NEW'!$C7)),0,1) -> 0 | V7: =IF(ISERROR(FIND(V$1,'Import_Add_Proc_(DE1-11) NEW'!$C7)),0,1) -> 0 | ... Y7: =IF(ISERROR(FIND(Y$1,'Import_Add_Proc_(DE1-11) NEW'!$C7)),0,1) -> 0 | Z7: =IF(ISERROR(FIND(Z$1,'Import_Add_Proc_(DE1-11) NEW'!$D7)),0,1) -> 0 | AA7: =IF(ISERROR(FIND(AA$1,'Import_Add_Proc_(DE1-11) NEW'!$D7)),0,1) -> 0 | AB7: =IF(ISERROR(FIND(AB$1,'Import_Add_Proc_(DE1-11) NEW'!$D7)),0,1) -> 0 | AC7: =IF(ISERROR(FIND(AC$1,'Import_Add_Proc_(DE1-11) NEW'!$D7)),0,1) -> 0 | AD7: =IF(ISERROR(FIND(AD$1,'Import_Add_Proc_(DE1-11) NEW'!$D7)),0,1) -> 0 | AE7: =IF(ISERROR(FIND(AE$1,'Import_Add_Proc_(DE1-11) NEW'!$D7)),0,1) -> 0 | AF7: =IF(ISERROR(FIND(AF$1,'Import_Add_Proc_(DE1-11) NEW'!$D7)),0,1) -> 0 | AG7: =IF(ISERROR(FIND(AG$1,'Import_Add_Proc_(DE1-11) NEW'!$D7)),0,1) -> 0 | ... AJ7: =IF(ISERROR(FIND(AJ$1,'Import_Add_Proc_(DE1-11) NEW'!$D7)),0,1) -> 0 | AK7: =IF(ISERROR(FIND(AK$1,'Import_Add_Proc_(DE1-11) NEW'!$E7)),0,1) -> 0 | AL7: =IF(ISERROR(FIND(AL$1,'Import_Add_Proc_(DE1-11) NEW'!$E7)),0,1) -> 1 | AM7: =IF(ISERROR(FIND(AM$1,'Import_Add_Proc_(DE1-11) NEW'!$E7)),0,1) -> 1 | AN7: =IF(ISERROR(FIND(AN$1,'Import_Add_Proc_(DE1-11) NEW'!$E7)),0,1) -> 0 | AO7: =IF(ISERROR(FIND(AO$1,'Import_Add_Proc_(DE1-11) NEW'!$E7)),0,1) -> 1 | AP7: =IF(ISERROR(FIND(AP$1,'Import_Add_Proc_(DE1-11) NEW'!$E7)),0,1) -> 1 | AQ7: =IF(ISERROR(FIND(AQ$1,'Import_Add_Proc_(DE1-11) NEW'!$E7)),0,1) -> 1 | AR7: =IF(ISERROR(FIND(AR$1,'Import_Add_Proc_(DE1-11) NEW'!$E7)),0,1) -> 1 | ... AU7: =IF(ISERROR(FIND(AU$1,'Import_Add_Proc_(DE1-11) NEW'!$E7)),0,1) -> 1 | AV7: =O7+Z7+AK7 -> 1 | AW7: =P7+AA7+AL7 -> 1 | AX7: =Q7+AB7+AM7 -> 1 | AY7: =R7+AC7+AN7 -> 1 | AZ7: =S7+AD7+AO7 -> 1 | BA7: =T7+AE7+AP7 -> 1 | BB7: =U7+AF7+AQ7 -> 1 | BC7: =V7+AG7+AR7 -> 1 | ... BF7: =Y7+AJ7+AU7 -> 1
A8: ='Import_Add_Proc_(DE1-11) NEW'!A8 -> C03 | B8: ='Import_Add_Proc_(DE1-11) NEW'!B8 -> N | C8: =IF(AV8<>1,"*",IF(O8,"P",IF(Z8,"R","N"))) -> P | D8: =IF(AW8<>1,"*",IF(P8,"P",IF(AA8,"R","N"))) -> N | E8: =IF(AX8<>1,"*",IF(Q8,"P",IF(AB8,"R","N"))) -> N | F8: =IF(AY8<>1,"*",IF(R8,"P",IF(AC8,"R","N"))) -> P | G8: =IF(AZ8<>1,"*",IF(S8,"P",IF(AD8,"R","N"))) -> N | H8: =IF(BA8<>1,"*",IF(T8,"P",IF(AE8,"R","N"))) -> N | I8: =IF(BB8<>1,"*",IF(U8,"P",IF(AF8,"R","N"))) -> N | J8: =IF(BC8<>1,"*",IF(V8,"P",IF(AG8,"R","N"))) -> N | ... M8: =IF(BF8<>1,"*",IF(Y8,"P",IF(AJ8,"R","N"))) -> N | N8: =IF(ISBLANK('Import_Add_Proc_(DE1-11) NEW'!F8),"",'Import_Add_Proc_(DE1-11) NEW'!F8) -> EIDR & SDP not permitted | O8: =IF(ISERROR(FIND(O$1,'Import_Add_Proc_(DE1-11) NEW'!$C8)),0,1) -> 1 | P8: =IF(ISERROR(FIND(P$1,'Import_Add_Proc_(DE1-11) NEW'!$C8)),0,1) -> 0 | Q8: =IF(ISERROR(FIND(Q$1,'Import_Add_Proc_(DE1-11) NEW'!$C8)),0,1) -> 0 | R8: =IF(ISERROR(FIND(R$1,'Import_Add_Proc_(DE1-11) NEW'!$C8)),0,1) -> 1 | S8: =IF(ISERROR(FIND(S$1,'Import_Add_Proc_(DE1-11) NEW'!$C8)),0,1) -> 0 | T8: =IF(ISERROR(FIND(T$1,'Import_Add_Proc_(DE1-11) NEW'!$C8)),0,1) -> 0 | U8: =IF(ISERROR(FIND(U$1,'Import_Add_Proc_(DE1-11) NEW'!$C8)),0,1) -> 0 | V8: =IF(ISERROR(FIND(V$1,'Import_Add_Proc_(DE1-11) NEW'!$C8)),0,1) -> 0 | ... Y8: =IF(ISERROR(FIND(Y$1,'Import_Add_Proc_(DE1-11) NEW'!$C8)),0,1) -> 0 | Z8: =IF(ISERROR(FIND(Z$1,'Import_Add_Proc_(DE1-11) NEW'!$D8)),0,1) -> 0 | AA8: =IF(ISERROR(FIND(AA$1,'Import_Add_Proc_(DE1-11) NEW'!$D8)),0,1) -> 0 | AB8: =IF(ISERROR(FIND(AB$1,'Import_Add_Proc_(DE1-11) NEW'!$D8)),0,1) -> 0 | AC8: =IF(ISERROR(FIND(AC$1,'Import_Add_Proc_(DE1-11) NEW'!$D8)),0,1) -> 0 | AD8: =IF(ISERROR(FIND(AD$1,'Import_Add_Proc_(DE1-11) NEW'!$D8)),0,1) -> 0 | AE8: =IF(ISERROR(FIND(AE$1,'Import_Add_Proc_(DE1-11) NEW'!$D8)),0,1) -> 0 | AF8: =IF(ISERROR(FIND(AF$1,'Import_Add_Proc_(DE1-11) NEW'!$D8)),0,1) -> 0 | AG8: =IF(ISERROR(FIND(AG$1,'Import_Add_Proc_(DE1-11) NEW'!$D8)),0,1) -> 0 | ... AJ8: =IF(ISERROR(FIND(AJ$1,'Import_Add_Proc_(DE1-11) NEW'!$D8)),0,1) -> 0 | AK8: =IF(ISERROR(FIND(AK$1,'Import_Add_Proc_(DE1-11) NEW'!$E8)),0,1) -> 0 | AL8: =IF(ISERROR(FIND(AL$1,'Import_Add_Proc_(DE1-11) NEW'!$E8)),0,1) -> 1 | AM8: =IF(ISERROR(FIND(AM$1,'Import_Add_Proc_(DE1-11) NEW'!$E8)),0,1) -> 1 | AN8: =IF(ISERROR(FIND(AN$1,'Import_Add_Proc_(DE1-11) NEW'!$E8)),0,1) -> 0 | AO8: =IF(ISERROR(FIND(AO$1,'Import_Add_Proc_(DE1-11) NEW'!$E8)),0,1) -> 1 | AP8: =IF(ISERROR(FIND(AP$1,'Import_Add_Proc_(DE1-11) NEW'!$E8)),0,1) -> 1 | AQ8: =IF(ISERROR(FIND(AQ$1,'Import_Add_Proc_(DE1-11) NEW'!$E8)),0,1) -> 1 | AR8: =IF(ISERROR(FIND(AR$1,'Import_Add_Proc_(DE1-11) NEW'!$E8)),0,1) -> 1 | ... AU8: =IF(ISERROR(FIND(AU$1,'Import_Add_Proc_(DE1-11) NEW'!$E8)),0,1) -> 1 | AV8: =O8+Z8+AK8 -> 1 | AW8: =P8+AA8+AL8 -> 1 | AX8: =Q8+AB8+AM8 -> 1 | AY8: =R8+AC8+AN8 -> 1 | AZ8: =S8+AD8+AO8 -> 1 | BA8: =T8+AE8+AP8 -> 1 | BB8: =U8+AF8+AQ8 -> 1 | BC8: =V8+AG8+AR8 -> 1 | ... BF8: =Y8+AJ8+AU8 -> 1
A9: ='Import_Add_Proc_(DE1-11) NEW'!A9 -> C04 | B9: ='Import_Add_Proc_(DE1-11) NEW'!B9 -> N | C9: =IF(AV9<>1,"*",IF(O9,"P",IF(Z9,"R","N"))) -> P | D9: =IF(AW9<>1,"*",IF(P9,"P",IF(AA9,"R","N"))) -> N | E9: =IF(AX9<>1,"*",IF(Q9,"P",IF(AB9,"R","N"))) -> R | F9: =IF(AY9<>1,"*",IF(R9,"P",IF(AC9,"R","N"))) -> P | G9: =IF(AZ9<>1,"*",IF(S9,"P",IF(AD9,"R","N"))) -> N | H9: =IF(BA9<>1,"*",IF(T9,"P",IF(AE9,"R","N"))) -> R | I9: =IF(BB9<>1,"*",IF(U9,"P",IF(AF9,"R","N"))) -> R | J9: =IF(BC9<>1,"*",IF(V9,"P",IF(AG9,"R","N"))) -> R | ... M9: =IF(BF9<>1,"*",IF(Y9,"P",IF(AJ9,"R","N"))) -> N | N9: =IF(ISBLANK('Import_Add_Proc_(DE1-11) NEW'!F9),"",'Import_Add_Proc_(DE1-11) NEW'!F9) -> EIDR & SDP only with rep status 3 | O9: =IF(ISERROR(FIND(O$1,'Import_Add_Proc_(DE1-11) NEW'!$C9)),0,1) -> 1 | P9: =IF(ISERROR(FIND(P$1,'Import_Add_Proc_(DE1-11) NEW'!$C9)),0,1) -> 0 | Q9: =IF(ISERROR(FIND(Q$1,'Import_Add_Proc_(DE1-11) NEW'!$C9)),0,1) -> 0 | R9: =IF(ISERROR(FIND(R$1,'Import_Add_Proc_(DE1-11) NEW'!$C9)),0,1) -> 1 | S9: =IF(ISERROR(FIND(S$1,'Import_Add_Proc_(DE1-11) NEW'!$C9)),0,1) -> 0 | T9: =IF(ISERROR(FIND(T$1,'Import_Add_Proc_(DE1-11) NEW'!$C9)),0,1) -> 0 | U9: =IF(ISERROR(FIND(U$1,'Import_Add_Proc_(DE1-11) NEW'!$C9)),0,1) -> 0 | V9: =IF(ISERROR(FIND(V$1,'Import_Add_Proc_(DE1-11) NEW'!$C9)),0,1) -> 0 | ... Y9: =IF(ISERROR(FIND(Y$1,'Import_Add_Proc_(DE1-11) NEW'!$C9)),0,1) -> 0 | Z9: =IF(ISERROR(FIND(Z$1,'Import_Add_Proc_(DE1-11) NEW'!$D9)),0,1) -> 0 | AA9: =IF(ISERROR(FIND(AA$1,'Import_Add_Proc_(DE1-11) NEW'!$D9)),0,1) -> 0 | AB9: =IF(ISERROR(FIND(AB$1,'Import_Add_Proc_(DE1-11) NEW'!$D9)),0,1) -> 1 | AC9: =IF(ISERROR(FIND(AC$1,'Import_Add_Proc_(DE1-11) NEW'!$D9)),0,1) -> 0 | AD9: =IF(ISERROR(FIND(AD$1,'Import_Add_Proc_(DE1-11) NEW'!$D9)),0,1) -> 0 | AE9: =IF(ISERROR(FIND(AE$1,'Import_Add_Proc_(DE1-11) NEW'!$D9)),0,1) -> 1 | AF9: =IF(ISERROR(FIND(AF$1,'Import_Add_Proc_(DE1-11) NEW'!$D9)),0,1) -> 1 | AG9: =IF(ISERROR(FIND(AG$1,'Import_Add_Proc_(DE1-11) NEW'!$D9)),0,1) -> 1 | ... AJ9: =IF(ISERROR(FIND(AJ$1,'Import_Add_Proc_(DE1-11) NEW'!$D9)),0,1) -> 0 | AK9: =IF(ISERROR(FIND(AK$1,'Import_Add_Proc_(DE1-11) NEW'!$E9)),0,1) -> 0 | AL9: =IF(ISERROR(FIND(AL$1,'Import_Add_Proc_(DE1-11) NEW'!$E9)),0,1) -> 1 | AM9: =IF(ISERROR(FIND(AM$1,'Import_Add_Proc_(DE1-11) NEW'!$E9)),0,1) -> 0 | AN9: =IF(ISERROR(FIND(AN$1,'Import_Add_Proc_(DE1-11) NEW'!$E9)),0,1) -> 0 | AO9: =IF(ISERROR(FIND(AO$1,'Import_Add_Proc_(DE1-11) NEW'!$E9)),0,1) -> 1 | AP9: =IF(ISERROR(FIND(AP$1,'Import_Add_Proc_(DE1-11) NEW'!$E9)),0,1) -> 0 | AQ9: =IF(ISERROR(FIND(AQ$1,'Import_Add_Proc_(DE1-11) NEW'!$E9)),0,1) -> 0 | AR9: =IF(ISERROR(FIND(AR$1,'Import_Add_Proc_(DE1-11) NEW'!$E9)),0,1) -> 0 | ... AU9: =IF(ISERROR(FIND(AU$1,'Import_Add_Proc_(DE1-11) NEW'!$E9)),0,1) -> 1 | AV9: =O9+Z9+AK9 -> 1 | AW9: =P9+AA9+AL9 -> 1 | AX9: =Q9+AB9+AM9 -> 1 | AY9: =R9+AC9+AN9 -> 1 | AZ9: =S9+AD9+AO9 -> 1 | BA9: =T9+AE9+AP9 -> 1 | BB9: =U9+AF9+AQ9 -> 1 | BC9: =V9+AG9+AR9 -> 1 | ... BF9: =Y9+AJ9+AU9 -> 1
A10: ='Import_Add_Proc_(DE1-11) NEW'!A10 -> C06 | B10: ='Import_Add_Proc_(DE1-11) NEW'!B10 -> N | C10: =IF(AV10<>1,"*",IF(O10,"P",IF(Z10,"R","N"))) -> P | D10: =IF(AW10<>1,"*",IF(P10,"P",IF(AA10,"R","N"))) -> N | E10: =IF(AX10<>1,"*",IF(Q10,"P",IF(AB10,"R","N"))) -> P | F10: =IF(AY10<>1,"*",IF(R10,"P",IF(AC10,"R","N"))) -> P | G10: =IF(AZ10<>1,"*",IF(S10,"P",IF(AD10,"R","N"))) -> N | H10: =IF(BA10<>1,"*",IF(T10,"P",IF(AE10,"R","N"))) -> P | I10: =IF(BB10<>1,"*",IF(U10,"P",IF(AF10,"R","N"))) -> P | J10: =IF(BC10<>1,"*",IF(V10,"P",IF(AG10,"R","N"))) -> P | ... M10: =IF(BF10<>1,"*",IF(Y10,"P",IF(AJ10,"R","N"))) -> N | N10: =IF(ISBLANK('Import_Add_Proc_(DE1-11) NEW'!F10),"",'Import_Add_Proc_(DE1-11) NEW'!F10) | O10: =IF(ISERROR(FIND(O$1,'Import_Add_Proc_(DE1-11) NEW'!$C10)),0,1) -> 1 | P10: =IF(ISERROR(FIND(P$1,'Import_Add_Proc_(DE1-11) NEW'!$C10)),0,1) -> 0 | Q10: =IF(ISERROR(FIND(Q$1,'Import_Add_Proc_(DE1-11) NEW'!$C10)),0,1) -> 1 | R10: =IF(ISERROR(FIND(R$1,'Import_Add_Proc_(DE1-11) NEW'!$C10)),0,1) -> 1 | S10: =IF(ISERROR(FIND(S$1,'Import_Add_Proc_(DE1-11) NEW'!$C10)),0,1) -> 0 | T10: =IF(ISERROR(FIND(T$1,'Import_Add_Proc_(DE1-11) NEW'!$C10)),0,1) -> 1 | U10: =IF(ISERROR(FIND(U$1,'Import_Add_Proc_(DE1-11) NEW'!$C10)),0,1) -> 1 | V10: =IF(ISERROR(FIND(V$1,'Import_Add_Proc_(DE1-11) NEW'!$C10)),0,1) -> 1 | ... Y10: =IF(ISERROR(FIND(Y$1,'Import_Add_Proc_(DE1-11) NEW'!$C10)),0,1) -> 0 | Z10: =IF(ISERROR(FIND(Z$1,'Import_Add_Proc_(DE1-11) NEW'!$D10)),0,1) -> 0 | AA10: =IF(ISERROR(FIND(AA$1,'Import_Add_Proc_(DE1-11) NEW'!$D10)),0,1) -> 0 | AB10: =IF(ISERROR(FIND(AB$1,'Import_Add_Proc_(DE1-11) NEW'!$D10)),0,1) -> 0 | AC10: =IF(ISERROR(FIND(AC$1,'Import_Add_Proc_(DE1-11) NEW'!$D10)),0,1) -> 0 | AD10: =IF(ISERROR(FIND(AD$1,'Import_Add_Proc_(DE1-11) NEW'!$D10)),0,1) -> 0 | AE10: =IF(ISERROR(FIND(AE$1,'Import_Add_Proc_(DE1-11) NEW'!$D10)),0,1) -> 0 | AF10: =IF(ISERROR(FIND(AF$1,'Import_Add_Proc_(DE1-11) NEW'!$D10)),0,1) -> 0 | AG10: =IF(ISERROR(FIND(AG$1,'Import_Add_Proc_(DE1-11) NEW'!$D10)),0,1) -> 0 | ... AJ10: =IF(ISERROR(FIND(AJ$1,'Import_Add_Proc_(DE1-11) NEW'!$D10)),0,1) -> 0 | AK10: =IF(ISERROR(FIND(AK$1,'Import_Add_Proc_(DE1-11) NEW'!$E10)),0,1) -> 0 | AL10: =IF(ISERROR(FIND(AL$1,'Import_Add_Proc_(DE1-11) NEW'!$E10)),0,1) -> 1 | AM10: =IF(ISERROR(FIND(AM$1,'Import_Add_Proc_(DE1-11) NEW'!$E10)),0,1) -> 0 | AN10: =IF(ISERROR(FIND(AN$1,'Import_Add_Proc_(DE1-11) NEW'!$E10)),0,1) -> 0 | AO10: =IF(ISERROR(FIND(AO$1,'Import_Add_Proc_(DE1-11) NEW'!$E10)),0,1) -> 1 | AP10: =IF(ISERROR(FIND(AP$1,'Import_Add_Proc_(DE1-11) NEW'!$E10)),0,1) -> 0 | AQ10: =IF(ISERROR(FIND(AQ$1,'Import_Add_Proc_(DE1-11) NEW'!$E10)),0,1) -> 0 | AR10: =IF(ISERROR(FIND(AR$1,'Import_Add_Proc_(DE1-11) NEW'!$E10)),0,1) -> 0 | ... AU10: =IF(ISERROR(FIND(AU$1,'Import_Add_Proc_(DE1-11) NEW'!$E10)),0,1) -> 1 | AV10: =O10+Z10+AK10 -> 1 | AW10: =P10+AA10+AL10 -> 1 | AX10: =Q10+AB10+AM10 -> 1 | AY10: =R10+AC10+AN10 -> 1 | AZ10: =S10+AD10+AO10 -> 1 | BA10: =T10+AE10+AP10 -> 1 | BB10: =U10+AF10+AQ10 -> 1 | BC10: =V10+AG10+AR10 -> 1 | ... BF10: =Y10+AJ10+AU10 -> 1
A11: ='Import_Add_Proc_(DE1-11) NEW'!A11 -> C07 | B11: ='Import_Add_Proc_(DE1-11) NEW'!B11 -> N | C11: =IF(AV11<>1,"*",IF(O11,"P",IF(Z11,"R","N"))) -> P | D11: =IF(AW11<>1,"*",IF(P11,"P",IF(AA11,"R","N"))) -> P | E11: =IF(AX11<>1,"*",IF(Q11,"P",IF(AB11,"R","N"))) -> P | F11: =IF(AY11<>1,"*",IF(R11,"P",IF(AC11,"R","N"))) -> P | G11: =IF(AZ11<>1,"*",IF(S11,"P",IF(AD11,"R","N"))) -> P | H11: =IF(BA11<>1,"*",IF(T11,"P",IF(AE11,"R","N"))) -> P | I11: =IF(BB11<>1,"*",IF(U11,"P",IF(AF11,"R","N"))) -> P | J11: =IF(BC11<>1,"*",IF(V11,"P",IF(AG11,"R","N"))) -> P | ... M11: =IF(BF11<>1,"*",IF(Y11,"P",IF(AJ11,"R","N"))) -> N | N11: =IF(ISBLANK('Import_Add_Proc_(DE1-11) NEW'!F11),"",'Import_Add_Proc_(DE1-11) NEW'!F11) | O11: =IF(ISERROR(FIND(O$1,'Import_Add_Proc_(DE1-11) NEW'!$C11)),0,1) -> 1 | P11: =IF(ISERROR(FIND(P$1,'Import_Add_Proc_(DE1-11) NEW'!$C11)),0,1) -> 1 | Q11: =IF(ISERROR(FIND(Q$1,'Import_Add_Proc_(DE1-11) NEW'!$C11)),0,1) -> 1 | R11: =IF(ISERROR(FIND(R$1,'Import_Add_Proc_(DE1-11) NEW'!$C11)),0,1) -> 1 | S11: =IF(ISERROR(FIND(S$1,'Import_Add_Proc_(DE1-11) NEW'!$C11)),0,1) -> 1 | T11: =IF(ISERROR(FIND(T$1,'Import_Add_Proc_(DE1-11) NEW'!$C11)),0,1) -> 1 | U11: =IF(ISERROR(FIND(U$1,'Import_Add_Proc_(DE1-11) NEW'!$C11)),0,1) -> 1 | V11: =IF(ISERROR(FIND(V$1,'Import_Add_Proc_(DE1-11) NEW'!$C11)),0,1) -> 1 | ... Y11: =IF(ISERROR(FIND(Y$1,'Import_Add_Proc_(DE1-11) NEW'!$C11)),0,1) -> 0 | Z11: =IF(ISERROR(FIND(Z$1,'Import_Add_Proc_(DE1-11) NEW'!$D11)),0,1) -> 0 | AA11: =IF(ISERROR(FIND(AA$1,'Import_Add_Proc_(DE1-11) NEW'!$D11)),0,1) -> 0 | AB11: =IF(ISERROR(FIND(AB$1,'Import_Add_Proc_(DE1-11) NEW'!$D11)),0,1) -> 0 | AC11: =IF(ISERROR(FIND(AC$1,'Import_Add_Proc_(DE1-11) NEW'!$D11)),0,1) -> 0 | AD11: =IF(ISERROR(FIND(AD$1,'Import_Add_Proc_(DE1-11) NEW'!$D11)),0,1) -> 0 | AE11: =IF(ISERROR(FIND(AE$1,'Import_Add_Proc_(DE1-11) NEW'!$D11)),0,1) -> 0 | AF11: =IF(ISERROR(FIND(AF$1,'Import_Add_Proc_(DE1-11) NEW'!$D11)),0,1) -> 0 | AG11: =IF(ISERROR(FIND(AG$1,'Import_Add_Proc_(DE1-11) NEW'!$D11)),0,1) -> 0 | ... AJ11: =IF(ISERROR(FIND(AJ$1,'Import_Add_Proc_(DE1-11) NEW'!$D11)),0,1) -> 0 | AK11: =IF(ISERROR(FIND(AK$1,'Import_Add_Proc_(DE1-11) NEW'!$E11)),0,1) -> 0 | AL11: =IF(ISERROR(FIND(AL$1,'Import_Add_Proc_(DE1-11) NEW'!$E11)),0,1) -> 0 | AM11: =IF(ISERROR(FIND(AM$1,'Import_Add_Proc_(DE1-11) NEW'!$E11)),0,1) -> 0 | AN11: =IF(ISERROR(FIND(AN$1,'Import_Add_Proc_(DE1-11) NEW'!$E11)),0,1) -> 0 | AO11: =IF(ISERROR(FIND(AO$1,'Import_Add_Proc_(DE1-11) NEW'!$E11)),0,1) -> 0 | AP11: =IF(ISERROR(FIND(AP$1,'Import_Add_Proc_(DE1-11) NEW'!$E11)),0,1) -> 0 | AQ11: =IF(ISERROR(FIND(AQ$1,'Import_Add_Proc_(DE1-11) NEW'!$E11)),0,1) -> 0 | AR11: =IF(ISERROR(FIND(AR$1,'Import_Add_Proc_(DE1-11) NEW'!$E11)),0,1) -> 0 | ... AU11: =IF(ISERROR(FIND(AU$1,'Import_Add_Proc_(DE1-11) NEW'!$E11)),0,1) -> 1 | AV11: =O11+Z11+AK11 -> 1 | AW11: =P11+AA11+AL11 -> 1 | AX11: =Q11+AB11+AM11 -> 1 | AY11: =R11+AC11+AN11 -> 1 | AZ11: =S11+AD11+AO11 -> 1 | BA11: =T11+AE11+AP11 -> 1 | BB11: =U11+AF11+AQ11 -> 1 | BC11: =V11+AG11+AR11 -> 1 | ... BF11: =Y11+AJ11+AU11 -> 1
A12: ='Import_Add_Proc_(DE1-11) NEW'!A12 -> C08 | B12: ='Import_Add_Proc_(DE1-11) NEW'!B12 -> N | C12: =IF(AV12<>1,"*",IF(O12,"P",IF(Z12,"R","N"))) -> P | D12: =IF(AW12<>1,"*",IF(P12,"P",IF(AA12,"R","N"))) -> P | E12: =IF(AX12<>1,"*",IF(Q12,"P",IF(AB12,"R","N"))) -> R | F12: =IF(AY12<>1,"*",IF(R12,"P",IF(AC12,"R","N"))) -> P | G12: =IF(AZ12<>1,"*",IF(S12,"P",IF(AD12,"R","N"))) -> P | H12: =IF(BA12<>1,"*",IF(T12,"P",IF(AE12,"R","N"))) -> R | I12: =IF(BB12<>1,"*",IF(U12,"P",IF(AF12,"R","N"))) -> R | J12: =IF(BC12<>1,"*",IF(V12,"P",IF(AG12,"R","N"))) -> R | ... M12: =IF(BF12<>1,"*",IF(Y12,"P",IF(AJ12,"R","N"))) -> N | N12: =IF(ISBLANK('Import_Add_Proc_(DE1-11) NEW'!F12),"",'Import_Add_Proc_(DE1-11) NEW'!F12) -> EIDR & SDP only with rep status 3 | O12: =IF(ISERROR(FIND(O$1,'Import_Add_Proc_(DE1-11) NEW'!$C12)),0,1) -> 1 | P12: =IF(ISERROR(FIND(P$1,'Import_Add_Proc_(DE1-11) NEW'!$C12)),0,1) -> 1 | Q12: =IF(ISERROR(FIND(Q$1,'Import_Add_Proc_(DE1-11) NEW'!$C12)),0,1) -> 0 | R12: =IF(ISERROR(FIND(R$1,'Import_Add_Proc_(DE1-11) NEW'!$C12)),0,1) -> 1 | S12: =IF(ISERROR(FIND(S$1,'Import_Add_Proc_(DE1-11) NEW'!$C12)),0,1) -> 1 | T12: =IF(ISERROR(FIND(T$1,'Import_Add_Proc_(DE1-11) NEW'!$C12)),0,1) -> 0 | U12: =IF(ISERROR(FIND(U$1,'Import_Add_Proc_(DE1-11) NEW'!$C12)),0,1) -> 0 | V12: =IF(ISERROR(FIND(V$1,'Import_Add_Proc_(DE1-11) NEW'!$C12)),0,1) -> 0 | ... Y12: =IF(ISERROR(FIND(Y$1,'Import_Add_Proc_(DE1-11) NEW'!$C12)),0,1) -> 0 | Z12: =IF(ISERROR(FIND(Z$1,'Import_Add_Proc_(DE1-11) NEW'!$D12)),0,1) -> 0 | AA12: =IF(ISERROR(FIND(AA$1,'Import_Add_Proc_(DE1-11) NEW'!$D12)),0,1) -> 0 | AB12: =IF(ISERROR(FIND(AB$1,'Import_Add_Proc_(DE1-11) NEW'!$D12)),0,1) -> 1 | AC12: =IF(ISERROR(FIND(AC$1,'Import_Add_Proc_(DE1-11) NEW'!$D12)),0,1) -> 0 | AD12: =IF(ISERROR(FIND(AD$1,'Import_Add_Proc_(DE1-11) NEW'!$D12)),0,1) -> 0 | AE12: =IF(ISERROR(FIND(AE$1,'Import_Add_Proc_(DE1-11) NEW'!$D12)),0,1) -> 1 | AF12: =IF(ISERROR(FIND(AF$1,'Import_Add_Proc_(DE1-11) NEW'!$D12)),0,1) -> 1 | AG12: =IF(ISERROR(FIND(AG$1,'Import_Add_Proc_(DE1-11) NEW'!$D12)),0,1) -> 1 | ... AJ12: =IF(ISERROR(FIND(AJ$1,'Import_Add_Proc_(DE1-11) NEW'!$D12)),0,1) -> 0 | AK12: =IF(ISERROR(FIND(AK$1,'Import_Add_Proc_(DE1-11) NEW'!$E12)),0,1) -> 0 | AL12: =IF(ISERROR(FIND(AL$1,'Import_Add_Proc_(DE1-11) NEW'!$E12)),0,1) -> 0 | AM12: =IF(ISERROR(FIND(AM$1,'Import_Add_Proc_(DE1-11) NEW'!$E12)),0,1) -> 0 | AN12: =IF(ISERROR(FIND(AN$1,'Import_Add_Proc_(DE1-11) NEW'!$E12)),0,1) -> 0 | AO12: =IF(ISERROR(FIND(AO$1,'Import_Add_Proc_(DE1-11) NEW'!$E12)),0,1) -> 0 | AP12: =IF(ISERROR(FIND(AP$1,'Import_Add_Proc_(DE1-11) NEW'!$E12)),0,1) -> 0 | AQ12: =IF(ISERROR(FIND(AQ$1,'Import_Add_Proc_(DE1-11) NEW'!$E12)),0,1) -> 0 | AR12: =IF(ISERROR(FIND(AR$1,'Import_Add_Proc_(DE1-11) NEW'!$E12)),0,1) -> 0 | ... AU12: =IF(ISERROR(FIND(AU$1,'Import_Add_Proc_(DE1-11) NEW'!$E12)),0,1) -> 1 | AV12: =O12+Z12+AK12 -> 1 | AW12: =P12+AA12+AL12 -> 1 | AX12: =Q12+AB12+AM12 -> 1 | AY12: =R12+AC12+AN12 -> 1 | AZ12: =S12+AD12+AO12 -> 1 | BA12: =T12+AE12+AP12 -> 1 | BB12: =U12+AF12+AQ12 -> 1 | BC12: =V12+AG12+AR12 -> 1 | ... BF12: =Y12+AJ12+AU12 -> 1
